<?xml version="1.0"?>
<!-- GENERATED by robot_assets from Onshape CAD. Do not edit by hand. Regenerate: robot-assets-generate lite_biped -->
<robot xmlns:xacro="http://www.ros.org/wiki/xacro">
  <xacro:macro name="lite_biped_description" params="mesh_root:=package://lite_description/robots/lite_biped/meshes/visual">
    <link name="base_link" />
    <joint name="base_link_to_pelvis" type="fixed">
      <parent link="base_link" />
      <child link="pelvis" />
      <origin xyz="0 0 0" rpy="0 0 0" />
    </joint>
    <!-- GENERATED by robot_assets from Onshape CAD. Do not edit by hand. Regenerate: robot-assets-generate lite_biped -->
    <link name="pelvis">
      <inertial>
        <origin xyz="0.0137049 6.97587e-07 0.0692011" rpy="0 0 0" />
        <mass value="2.1" />
        <inertia ixx="0.00987937" ixy="3.9803e-08" ixz="-0.000115563" iyy="0.00823366" iyz="-5.1965e-08" izz="0.00638151" />
      </inertial>
      <!-- Part pelvis_parts -->
      <visual>
        <origin xyz="0.0137049 6.97587e-07 0.0692011" rpy="0 -0 0" />
        <geometry>
          <mesh filename="${mesh_root}/pelvis_visual.stl" />
        </geometry>
        <material name="pelvis_parts_material">
          <color rgba="0.933333 0.933333 0.933333 1" />
        </material>
      </visual>
    </link>
    <!-- Frame imu (dummy link + fixed joint) -->
    <link name="imu">
      <origin xyz="0 0 0" rpy="0 -0 0" />
      <inertial>
        <origin xyz="0 0 0" rpy="0 0 0" />
        <mass value="1e-9" />
        <inertia ixx="0" ixy="0" ixz="0" iyy="0" iyz="0" izz="0" />
      </inertial>
    </link>
    <joint name="imu_frame" type="fixed">
      <origin xyz="0 0 0.08" rpy="0 -0 0" />
      <parent link="pelvis" />
      <child link="imu" />
      <axis xyz="0 0 0" />
    </joint>
    <!-- Link left_hip_pitch -->
    <link name="left_hip_pitch">
      <inertial>
        <origin xyz="-0.0114774 0.00418673 0.0187959" rpy="0 0 0" />
        <mass value="0.18" />
        <inertia ixx="0.000189549" ixy="1.56103e-05" ixz="-3.45388e-05" iyy="0.000226363" iyz="1.30141e-05" izz="0.000286537" />
      </inertial>
      <!-- Part left_hip_pitch_parts -->
      <visual>
        <origin xyz="-0.0114774 0.00418673 0.0187959" rpy="1.74533 0 -0" />
        <geometry>
          <mesh filename="${mesh_root}/left_hip_pitch_visual.stl" />
        </geometry>
        <material name="left_hip_pitch_parts_material">
          <color rgba="0.933333 0.933333 0.933333 1" />
        </material>
      </visual>
    </link>
    <!-- Link left_hip_roll -->
    <link name="left_hip_roll">
      <inertial>
        <origin xyz="-4.8952e-08 0.0525082 -0.0652484" rpy="0 0 0" />
        <mass value="0.93" />
        <inertia ixx="0.00263146" ixy="-5.134e-09" ixz="3.451e-09" iyy="0.00142387" iyz="-0.000651416" izz="0.00255491" />
      </inertial>
      <!-- Part left_hip_roll_parts -->
      <collision>
        <origin xyz="0 0.181098 -0.0871979" rpy="1.22173 -0 0" />
        <geometry>
          <cylinder length="0.15" radius="0.05" />
        </geometry>
      </collision>
      <visual>
        <origin xyz="-4.8952e-08 0.0525082 -0.0652484" rpy="0 -1.22173 1.5708" />
        <geometry>
          <mesh filename="${mesh_root}/left_hip_roll_visual.stl" />
        </geometry>
        <material name="left_hip_roll_parts_material">
          <color rgba="0.933333 0.933333 0.933333 1" />
        </material>
      </visual>
    </link>
    <!-- Link left_hip_yaw -->
    <link name="left_hip_yaw">
      <inertial>
        <origin xyz="0.00130442 -2.2783e-05 -0.237299" rpy="0 0 0" />
        <mass value="1.54" />
        <inertia ixx="0.00856423" ixy="8.05553e-07" ixz="-0.000337563" iyy="0.00874707" iyz="1.62929e-07" izz="0.00192866" />
      </inertial>
      <!-- Part left_hip_yaw_parts -->
      <visual>
        <origin xyz="0.00130442 -2.2783e-05 -0.237299" rpy="-0 0 -0" />
        <geometry>
          <mesh filename="${mesh_root}/left_hip_yaw_visual.stl" />
        </geometry>
        <material name="left_hip_yaw_parts_material">
          <color rgba="0.933333 0.933333 0.933333 1" />
        </material>
      </visual>
    </link>
    <!-- Link left_knee_pitch -->
    <link name="left_knee_pitch">
      <inertial>
        <origin xyz="-0.00486713 0.0372163 -0.000224083" rpy="0 0 0" />
        <mass value="0.23" />
        <inertia ixx="0.00048246" ixy="3.51526e-05" ixz="-1.20098e-07" iyy="0.000330466" iyz="5.6617e-07" izz="0.00037756" />
      </inertial>
      <!-- Part left_knee_pitch_parts -->
      <collision>
        <origin xyz="-0.015 0.19 0" rpy="1.5708 1.5708 0" />
        <geometry>
          <cylinder length="0.12" radius="0.045" />
        </geometry>
      </collision>
      <visual>
        <origin xyz="-0.00486713 0.0372163 -0.000224083" rpy="1.5708 0 0" />
        <geometry>
          <mesh filename="${mesh_root}/left_knee_pitch_visual.stl" />
        </geometry>
        <material name="left_knee_pitch_parts_material">
          <color rgba="0.933333 0.933333 0.933333 1" />
        </material>
      </visual>
    </link>
    <!-- Link left_ankle_yaw -->
    <link name="left_ankle_yaw">
      <inertial>
        <origin xyz="-0.00304992 0.00150525 -0.18535" rpy="0 0 0" />
        <mass value="1.03" />
        <inertia ixx="0.00548966" ixy="2.18778e-06" ixz="0.000114943" iyy="0.00552969" iyz="-1.87643e-05" izz="0.000829513" />
      </inertial>
      <!-- Part left_ankle_yaw_parts -->
      <visual>
        <origin xyz="-0.00304992 0.00150525 -0.18535" rpy="-0 0 -0" />
        <geometry>
          <mesh filename="${mesh_root}/left_ankle_yaw_visual.stl" />
        </geometry>
        <material name="left_ankle_yaw_parts_material">
          <color rgba="0.933333 0.933333 0.933333 1" />
        </material>
      </visual>
    </link>
    <!-- Link left_ankle_pitch -->
    <link name="left_ankle_pitch">
      <inertial>
        <origin xyz="-0.00384209 0.0297371 3.1356e-08" rpy="0 0 0" />
        <mass value="0.34" />
        <inertia ixx="0.000180143" ixy="-3.10163e-05" ixz="-7.8e-11" iyy="0.00014325" iyz="2.66e-10" izz="0.000245142" />
      </inertial>
      <!-- Part left_ankle_pitch_parts -->
      <visual>
        <origin xyz="-0.00384209 0.0297371 3.1356e-08" rpy="1.5708 -0 -0" />
        <geometry>
          <mesh filename="${mesh_root}/left_ankle_pitch_visual.stl" />
        </geometry>
        <material name="left_ankle_pitch_parts_material">
          <color rgba="0.933333 0.933333 0.933333 1" />
        </material>
      </visual>
    </link>
    <!-- Link left_foot -->
    <link name="left_foot">
      <inertial>
        <origin xyz="0.00124938 0.0227876 0.0398042" rpy="0 0 0" />
        <mass value="0.44" />
        <inertia ixx="0.00133847" ixy="-3.31857e-06" ixz="-4.29633e-05" iyy="0.00119465" iyz="-0.000154848" izz="0.000481763" />
      </inertial>
      <!-- Part left_foot_parts -->
      <collision>
        <origin xyz="0 0.05 0.015" rpy="1.5708 0 0" />
        <geometry>
          <box size="0.065 0.12 0.03" />
        </geometry>
      </collision>
      <collision>
        <origin xyz="0 0.04 0.11" rpy="1.91986 0 0" />
        <geometry>
          <box size="0.07 0.05 0.03" />
        </geometry>
      </collision>
      <visual>
        <origin xyz="0.00124938 0.0227876 0.0398042" rpy="1.5708 -1.5708 0" />
        <geometry>
          <mesh filename="${mesh_root}/left_foot_visual.stl" />
        </geometry>
        <material name="left_foot_parts_material">
          <color rgba="0.933333 0.933333 0.933333 1" />
        </material>
      </visual>
    </link>
    <!-- Joint from left_ankle_pitch to left_foot -->
    <joint name="left_ankle_roll" type="revolute">
      <origin xyz="-0 0.04 0" rpy="0 1.5708 0" />
      <parent link="left_ankle_pitch" />
      <child link="left_foot" />
      <axis xyz="0 0 1" />
      <limit effort="5.5" velocity="100" lower="-0.349066" upper="0.349066" />
      <joint_properties friction="0.1" />
    </joint>
    <!-- Joint from left_ankle_yaw to left_ankle_pitch -->
    <joint name="left_ankle_pitch" type="revolute">
      <origin xyz="0.01 -0 -0.34" rpy="-1.5708 0 -0" />
      <parent link="left_ankle_yaw" />
      <child link="left_ankle_pitch" />
      <axis xyz="0 0 1" />
      <limit effort="14.0" velocity="100" lower="-0.523599" upper="0.872665" />
      <joint_properties friction="0.1" />
    </joint>
    <!-- Joint from left_knee_pitch to left_ankle_yaw -->
    <joint name="left_ankle_yaw" type="revolute">
      <origin xyz="-0.015 0 0" rpy="1.5708 0 -0" />
      <parent link="left_knee_pitch" />
      <child link="left_ankle_yaw" />
      <axis xyz="0 0 1" />
      <limit effort="14.0" velocity="100" lower="-1.5708" upper="1.5708" />
      <joint_properties friction="0.1" />
    </joint>
    <!-- Joint from left_hip_yaw to left_knee_pitch -->
    <joint name="left_knee_pitch" type="revolute">
      <origin xyz="-0.01 0 -0.33" rpy="-1.5708 0 0" />
      <parent link="left_hip_yaw" />
      <child link="left_knee_pitch" />
      <axis xyz="0 0 1" />
      <limit effort="36.0" velocity="100" lower="0" upper="2.35619" />
      <joint_properties friction="0.1" />
    </joint>
    <!-- Joint from left_hip_roll to left_hip_yaw -->
    <joint name="left_hip_yaw" type="revolute">
      <origin xyz="0 -0.0068404 -0.0187939" rpy="0 -1.22173 1.5708" />
      <parent link="left_hip_roll" />
      <child link="left_hip_yaw" />
      <axis xyz="0 0 1" />
      <limit effort="17.0" velocity="100" lower="-1.5708" upper="1.5708" />
      <joint_properties friction="0.1" />
    </joint>
    <!-- Joint from left_hip_pitch to left_hip_roll -->
    <joint name="left_hip_roll" type="revolute">
      <origin xyz="-0 0 -0" rpy="1.91986 1.39626 1.5708" />
      <parent link="left_hip_pitch" />
      <child link="left_hip_roll" />
      <axis xyz="0 0 1" />
      <limit effort="36.0" velocity="100" lower="-0.349066" upper="1.5708" />
      <joint_properties friction="0.1" />
    </joint>
    <!-- Joint from pelvis to left_hip_pitch -->
    <joint name="left_hip_pitch" type="revolute">
      <origin xyz="0.02 0.07 0" rpy="-1.74533 0 0" />
      <parent link="pelvis" />
      <child link="left_hip_pitch" />
      <axis xyz="0 0 1" />
      <limit effort="36.0" velocity="100" lower="-2.35619" upper="0.785398" />
      <joint_properties friction="0.1" />
    </joint>
    <!-- Link right_hip_pitch -->
    <link name="right_hip_pitch">
      <inertial>
        <origin xyz="-0.0114771 0.00418737 -0.0187964" rpy="0 0 0" />
        <mass value="0.18" />
        <inertia ixx="0.000189546" ixy="1.56176e-05" ixz="3.45408e-05" iyy="0.00022637" iyz="-1.30122e-05" izz="0.000286535" />
      </inertial>
      <!-- Part right_hip_pitch_parts -->
      <visual>
        <origin xyz="-0.0114771 0.00418737 -0.0187964" rpy="1.39626 0 -0" />
        <geometry>
          <mesh filename="${mesh_root}/right_hip_pitch_visual.stl" />
        </geometry>
        <material name="right_hip_pitch_parts_material">
          <color rgba="0.933333 0.933333 0.933333 1" />
        </material>
      </visual>
    </link>
    <!-- Link right_hip_roll -->
    <link name="right_hip_roll">
      <inertial>
        <origin xyz="-1.13349e-07 0.0525083 -0.0652488" rpy="0 0 0" />
        <mass value="0.93" />
        <inertia ixx="0.00263147" ixy="2.71e-10" ixz="6.079e-09" iyy="0.00142387" iyz="-0.000651423" izz="0.00255493" />
      </inertial>
      <!-- Part right_hip_roll_parts -->
      <collision>
        <origin xyz="-0 0.181098 -0.0871979" rpy="1.22173 0 0" />
        <geometry>
          <cylinder length="0.15" radius="0.05" />
        </geometry>
      </collision>
      <visual>
        <origin xyz="-1.13349e-07 0.0525083 -0.0652488" rpy="0 -1.22173 1.5708" />
        <geometry>
          <mesh filename="${mesh_root}/right_hip_roll_visual.stl" />
        </geometry>
        <material name="right_hip_roll_parts_material">
          <color rgba="0.933333 0.933333 0.933333 1" />
        </material>
      </visual>
    </link>
    <!-- Link right_hip_yaw -->
    <link name="right_hip_yaw">
      <inertial>
        <origin xyz="0.00130421 2.35733e-05 -0.237299" rpy="0 0 0" />
        <mass value="1.54" />
        <inertia ixx="0.00856421" ixy="-7.98006e-07" ixz="-0.000337552" iyy="0.00874705" iyz="-2.23692e-07" izz="0.00192867" />
      </inertial>
      <!-- Part right_hip_yaw_parts -->
      <visual>
        <origin xyz="0.00130421 2.35733e-05 -0.237299" rpy="0 0 0" />
        <geometry>
          <mesh filename="${mesh_root}/right_hip_yaw_visual.stl" />
        </geometry>
        <material name="right_hip_yaw_parts_material">
          <color rgba="0.933333 0.933333 0.933333 1" />
        </material>
      </visual>
    </link>
    <!-- Link right_knee_pitch -->
    <link name="right_knee_pitch">
      <inertial>
        <origin xyz="-0.0048642 0.0372186 0.000224747" rpy="0 0 0" />
        <mass value="0.23" />
        <inertia ixx="0.000482479" ixy="3.5171e-05" ixz="1.13103e-07" iyy="0.000330463" iyz="-5.54061e-07" izz="0.000377561" />
      </inertial>
      <!-- Part right_knee_pitch_parts -->
      <collision>
        <origin xyz="-0.015 0.19 0" rpy="1.5708 1.5708 0" />
        <geometry>
          <cylinder length="0.12" radius="0.045" />
        </geometry>
      </collision>
      <visual>
        <origin xyz="-0.0048642 0.0372186 0.000224747" rpy="1.5708 -0 0" />
        <geometry>
          <mesh filename="${mesh_root}/right_knee_pitch_visual.stl" />
        </geometry>
        <material name="right_knee_pitch_parts_material">
          <color rgba="0.933333 0.933333 0.933333 1" />
        </material>
      </visual>
    </link>
    <!-- Link right_ankle_yaw -->
    <link name="right_ankle_yaw">
      <inertial>
        <origin xyz="-0.00304908 -0.0015054 -0.185348" rpy="0 0 0" />
        <mass value="1.03" />
        <inertia ixx="0.00548969" ixy="-2.19478e-06" ixz="0.000114953" iyy="0.00552968" iyz="1.87697e-05" izz="0.00082951" />
      </inertial>
      <!-- Part right_ankle_yaw_parts -->
      <visual>
        <origin xyz="-0.00304908 -0.0015054 -0.185348" rpy="0 0 0" />
        <geometry>
          <mesh filename="${mesh_root}/right_ankle_yaw_visual.stl" />
        </geometry>
        <material name="right_ankle_yaw_parts_material">
          <color rgba="0.933333 0.933333 0.933333 1" />
        </material>
      </visual>
    </link>
    <!-- Link right_ankle_pitch -->
    <link name="right_ankle_pitch">
      <inertial>
        <origin xyz="-0.00384209 0.0297371 3.1396e-08" rpy="0 0 0" />
        <mass value="0.34" />
        <inertia ixx="0.000180143" ixy="-3.10163e-05" ixz="-7.8e-11" iyy="0.00014325" iyz="2.66e-10" izz="0.000245142" />
      </inertial>
      <!-- Part right_ankle_pitch_parts -->
      <visual>
        <origin xyz="-0.00384209 0.0297371 3.1396e-08" rpy="1.5708 -0 0" />
        <geometry>
          <mesh filename="${mesh_root}/right_ankle_pitch_visual.stl" />
        </geometry>
        <material name="right_ankle_pitch_parts_material">
          <color rgba="0.933333 0.933333 0.933333 1" />
        </material>
      </visual>
    </link>
    <!-- Link right_foot -->
    <link name="right_foot">
      <inertial>
        <origin xyz="-0.0012494 0.0227876 0.039804" rpy="0 0 0" />
        <mass value="0.44" />
        <inertia ixx="0.00133847" ixy="3.3182e-06" ixz="4.29635e-05" iyy="0.00119465" iyz="-0.000154847" izz="0.000481763" />
      </inertial>
      <!-- Part right_foot_parts -->
      <collision>
        <origin xyz="0 0.05 0.015" rpy="1.5708 0 -0" />
        <geometry>
          <box size="0.065 0.12 0.03" />
        </geometry>
      </collision>
      <collision>
        <origin xyz="0 0.04 0.11" rpy="1.91986 0 -0" />
        <geometry>
          <box size="0.07 0.05 0.03" />
        </geometry>
      </collision>
      <visual>
        <origin xyz="-0.0012494 0.0227876 0.039804" rpy="1.5708 -1.5708 0" />
        <geometry>
          <mesh filename="${mesh_root}/right_foot_visual.stl" />
        </geometry>
        <material name="right_foot_parts_material">
          <color rgba="0.933333 0.933333 0.933333 1" />
        </material>
      </visual>
    </link>
    <!-- Joint from right_ankle_pitch to right_foot -->
    <joint name="right_ankle_roll" type="revolute">
      <origin xyz="-0 0.04 -0" rpy="-0 1.5708 0" />
      <parent link="right_ankle_pitch" />
      <child link="right_foot" />
      <axis xyz="0 0 1" />
      <limit effort="5.5" velocity="100" lower="-0.349066" upper="0.349066" />
      <joint_properties friction="0.1" />
    </joint>
    <!-- Joint from right_ankle_yaw to right_ankle_pitch -->
    <joint name="right_ankle_pitch" type="revolute">
      <origin xyz="0.01 0 -0.34" rpy="-1.5708 0 0" />
      <parent link="right_ankle_yaw" />
      <child link="right_ankle_pitch" />
      <axis xyz="0 0 1" />
      <limit effort="14.0" velocity="100" lower="-0.523599" upper="0.872665" />
      <joint_properties friction="0.1" />
    </joint>
    <!-- Joint from right_knee_pitch to right_ankle_yaw -->
    <joint name="right_ankle_yaw" type="revolute">
      <origin xyz="-0.015 0 -0" rpy="1.5708 -0 -0" />
      <parent link="right_knee_pitch" />
      <child link="right_ankle_yaw" />
      <axis xyz="0 0 1" />
      <limit effort="14.0" velocity="100" lower="-1.5708" upper="1.5708" />
      <joint_properties friction="0.1" />
    </joint>
    <!-- Joint from right_hip_yaw to right_knee_pitch -->
    <joint name="right_knee_pitch" type="revolute">
      <origin xyz="-0.01 -0 -0.33" rpy="-1.5708 0 0" />
      <parent link="right_hip_yaw" />
      <child link="right_knee_pitch" />
      <axis xyz="0 0 1" />
      <limit effort="36.0" velocity="100" lower="0" upper="2.35619" />
      <joint_properties friction="0.1" />
    </joint>
    <!-- Joint from right_hip_roll to right_hip_yaw -->
    <joint name="right_hip_yaw" type="revolute">
      <origin xyz="-0 -0.0068404 -0.0187939" rpy="0 -1.22173 1.5708" />
      <parent link="right_hip_roll" />
      <child link="right_hip_yaw" />
      <axis xyz="0 0 1" />
      <limit effort="17.0" velocity="100" lower="-1.5708" upper="1.5708" />
      <joint_properties friction="0.1" />
    </joint>
    <!-- Joint from right_hip_pitch to right_hip_roll -->
    <joint name="right_hip_roll" type="revolute">
      <origin xyz="0 -0 -0" rpy="-1.22173 1.39626 -1.5708" />
      <parent link="right_hip_pitch" />
      <child link="right_hip_roll" />
      <axis xyz="0 0 1" />
      <limit effort="36.0" velocity="100" lower="-1.5708" upper="0.349066" />
      <joint_properties friction="0.1" />
    </joint>
    <!-- Joint from pelvis to right_hip_pitch -->
    <joint name="right_hip_pitch" type="revolute">
      <origin xyz="0.02 -0.07 -0" rpy="-1.39626 -0 0" />
      <parent link="pelvis" />
      <child link="right_hip_pitch" />
      <axis xyz="0 0 1" />
      <limit effort="36.0" velocity="100" lower="-2.35619" upper="0.785398" />
      <joint_properties friction="0.1" />
    </joint>
  </xacro:macro>
</robot>
