<?xml version='1.0' encoding='utf-8'?>
<mujoco model="lite_biped">
  <!-- GENERATED by robot_assets from Onshape CAD. Do not edit by hand. Regenerate: robot-assets-generate lite_biped -->
  <compiler angle="radian" meshdir="../meshes/visual/" />

  <option timestep="0.001" integrator="implicitfast" solver="Newton" cone="elliptic" impratio="10" /><asset>
    <mesh name="pelvis_visual" content_type="model/stl" file="pelvis_visual.stl" />
    <mesh name="left_hip_pitch_visual" content_type="model/stl" file="left_hip_pitch_visual.stl" />
    <mesh name="left_hip_roll_visual" content_type="model/stl" file="left_hip_roll_visual.stl" />
    <mesh name="left_hip_yaw_visual" content_type="model/stl" file="left_hip_yaw_visual.stl" />
    <mesh name="left_knee_pitch_visual" content_type="model/stl" file="left_knee_pitch_visual.stl" />
    <mesh name="left_ankle_yaw_visual" content_type="model/stl" file="left_ankle_yaw_visual.stl" />
    <mesh name="left_ankle_pitch_visual" content_type="model/stl" file="left_ankle_pitch_visual.stl" />
    <mesh name="left_foot_visual" content_type="model/stl" file="left_foot_visual.stl" />
    <mesh name="right_hip_pitch_visual" content_type="model/stl" file="right_hip_pitch_visual.stl" />
    <mesh name="right_hip_roll_visual" content_type="model/stl" file="right_hip_roll_visual.stl" />
    <mesh name="right_hip_yaw_visual" content_type="model/stl" file="right_hip_yaw_visual.stl" />
    <mesh name="right_knee_pitch_visual" content_type="model/stl" file="right_knee_pitch_visual.stl" />
    <mesh name="right_ankle_yaw_visual" content_type="model/stl" file="right_ankle_yaw_visual.stl" />
    <mesh name="right_ankle_pitch_visual" content_type="model/stl" file="right_ankle_pitch_visual.stl" />
    <mesh name="right_foot_visual" content_type="model/stl" file="right_foot_visual.stl" />
  </asset>

  <worldbody>
    <body name="pelvis">
      <inertial pos="0.0135183 5.78646e-07 0.0691358" quat="0.999848 -1.33806e-05 0.0174073 1.226e-05" mass="3.97182" diaginertia="0.0186941 0.015546 0.0121291" />
      <geom pos="0.0135183 5.78646e-07 0.0691358" type="mesh" contype="0" conaffinity="0" group="1" density="0" rgba="0.933333 0.933333 0.933333 1" mesh="pelvis_visual" />
      <body name="left_hip_pitch" pos="0.02 0.07 0" quat="0.642787 -0.766045 0 0">
        <inertial pos="-0.0114774 0.00418673 0.0187959" quat="0.143691 0.579874 -0.102327 0.795379" mass="0.619442" diaginertia="0.00102698 0.000798701 0.000591686" />
        <joint name="left_hip_pitch" pos="0 0 0" axis="0 0 1" range="-2.35619 0.785398" actuatorfrcrange="-97 97" frictionloss="0.1" armature="0.03" />
        <geom pos="-0.0114774 0.00418673 0.0187959" quat="0.642787 0.766045 0 0" type="mesh" contype="0" conaffinity="0" group="1" density="0" rgba="0.933333 0.933333 0.933333 1" mesh="left_hip_pitch_visual" />
        <body name="left_hip_roll" quat="0.683013 0.183012 0.704417 -0.0616252">
          <inertial pos="-4.8952e-08 0.0525082 -0.0652484" quat="0.382435 0.594773 -0.59476 0.382425" mass="1.30369" diaginertia="0.00399804 0.00368883 0.0015795" />
          <joint name="left_hip_roll" pos="0 0 0" axis="0 0 1" range="-0.349066 1.5708" actuatorfrcrange="-97 97" frictionloss="0.1" armature="0.03" />
          <geom size="0.05 0.075" pos="0 0.181098 -0.0871979" quat="0.819152 0.573576 0 0" type="capsule" />
          <geom pos="-4.8952e-08 0.0525082 -0.0652484" quat="0.579227 0.40558 -0.405579 0.579229" type="mesh" contype="0" conaffinity="0" group="1" density="0" rgba="0.933333 0.933333 0.933333 1" mesh="left_hip_roll_visual" />
          <body name="left_hip_yaw" pos="0 -0.0068404 -0.0187939" quat="0.579227 0.40558 -0.405579 0.579229">
            <inertial pos="0.00130442 -2.2783e-05 -0.237299" quat="0.708576 0.0178897 0.0179548 0.705179" mass="2.08958" diaginertia="0.0118686 0.0116437 0.0025937" />
            <joint name="left_hip_yaw" pos="0 0 0" axis="0 0 1" range="-1.5708 1.5708" actuatorfrcrange="-97 97" frictionloss="0.1" armature="0.03" />
            <geom pos="0.00130442 -2.2783e-05 -0.237299" quat="1 0 0 0" type="mesh" contype="0" conaffinity="0" group="1" density="0" rgba="0.933333 0.933333 0.933333 1" mesh="left_hip_yaw_visual" />
            <body name="left_knee_pitch" pos="-0.01 0 -0.33" quat="0.707105 -0.707108 0 0">
              <inertial pos="-0.00486713 0.0372163 -0.000224083" quat="0.706661 0.699245 0.0760196 0.0768537" mass="0.435399" diaginertia="0.000927962 0.000714748 0.000610929" />
              <joint name="left_knee_pitch" pos="0 0 0" axis="0 0 1" range="0 2.35619" actuatorfrcrange="-97 97" frictionloss="0.1" armature="0.03" />
              <geom size="0.045 0.08" pos="-0.01 0.17 0" quat="0.499998 0.5 0.5 -0.500002" type="capsule" />
              <geom pos="-0.00486713 0.0372163 -0.000224083" quat="0.707105 0.707108 0 0" type="mesh" contype="0" conaffinity="0" group="1" density="0" rgba="0.933333 0.933333 0.933333 1" mesh="left_knee_pitch_visual" />
              <body name="left_ankle_yaw" pos="-0.015 0 0" quat="0.707105 0.707108 0 0">
                <inertial pos="-0.00304992 0.00150525 -0.18535" quat="0.723193 -0.00995668 -0.00753122 0.690534" mass="1.43174" diaginertia="0.00768669 0.00763466 0.00114901" />
                <joint name="left_ankle_yaw" pos="0 0 0" axis="0 0 1" range="-0.785398 0.785398" actuatorfrcrange="-27 27" frictionloss="0.1" armature="0.01" />
                <geom pos="-0.00304992 0.00150525 -0.18535" quat="1 0 0 0" type="mesh" contype="0" conaffinity="0" group="1" density="0" rgba="0.933333 0.933333 0.933333 1" mesh="left_ankle_yaw_visual" />
                <body name="left_ankle_pitch" pos="0.01 0 -0.34" quat="0.707105 -0.707108 0 0">
                  <inertial pos="-0.00384209 0.0297371 3.1356e-08" quat="0.611225 0.355531 -0.611226 0.355534" mass="0.184118" diaginertia="0.00013275 0.000107104 6.80202e-05" />
                  <joint name="left_ankle_pitch" pos="0 0 0" axis="0 0 1" range="-0.523599 0.872665" actuatorfrcrange="-27 27" frictionloss="0.1" armature="0.01" />
                  <geom pos="-0.00384209 0.0297371 3.1356e-08" quat="0.707105 0.707108 0 0" type="mesh" contype="0" conaffinity="0" group="1" density="0" rgba="0.933333 0.933333 0.933333 1" mesh="left_ankle_pitch_visual" />
                  <body name="left_foot" pos="0 0.04 0" quat="0.707105 0 0.707108 0">
                    <inertial pos="0.00124938 0.0227876 0.0398042" quat="0.994259 -0.101477 0.0262886 0.0214671" mass="1.20654" diaginertia="0.00367661 0.00336341 0.00122719" />
                    <joint name="left_ankle_roll" pos="0 0 0" axis="0 0 1" range="-0.349066 0.349066" actuatorfrcrange="-5.5 5.5" frictionloss="0.1" armature="0.001" />
                    <geom size="0.0325 0.06 0.015" pos="0 0.08 0.015" quat="0.707105 0.707108 0 0" type="box" />
                    <geom size="0.035 0.025 0.015" pos="0 0.07 0.11" quat="0.573577 0.819151 0 0" type="box" />
                    <geom pos="0.00124938 0.0227876 0.0398042" quat="0.499998 0.5 -0.5 0.500002" type="mesh" contype="0" conaffinity="0" group="1" density="0" rgba="0.933333 0.933333 0.933333 1" mesh="left_foot_visual" />
                  </body>
                </body>
              </body>
            </body>
          </body>
        </body>
      </body>
      <body name="right_hip_pitch" pos="0.02 -0.07 0" quat="0.766046 -0.642786 0 0">
        <inertial pos="-0.0114771 0.00418737 -0.0187964" quat="0.10235 0.795381 -0.143679 0.579871" mass="0.619423" diaginertia="0.00102695 0.000798714 0.000591646" />
        <joint name="right_hip_pitch" pos="0 0 0" axis="0 0 1" range="-2.35619 0.785398" actuatorfrcrange="-97 97" frictionloss="0.1" armature="0.03" />
        <geom pos="-0.0114771 0.00418737 -0.0187964" quat="0.766046 0.642786 0 0" type="mesh" contype="0" conaffinity="0" group="1" density="0" rgba="0.933333 0.933333 0.933333 1" mesh="right_hip_pitch_visual" />
        <body name="right_hip_roll" quat="0.704416 0.0616286 0.683012 -0.183015">
          <inertial pos="-1.13349e-07 0.0525083 -0.0652488" quat="0.382434 0.594774 -0.594759 0.382426" mass="1.30368" diaginertia="0.00399801 0.0036888 0.00157947" />
          <joint name="right_hip_roll" pos="0 0 0" axis="0 0 1" range="-1.5708 0.349066" actuatorfrcrange="-97 97" frictionloss="0.1" armature="0.03" />
          <geom size="0.05 0.075" pos="0 0.181098 -0.0871979" quat="0.819152 0.573576 0 0" type="capsule" />
          <geom pos="-1.13349e-07 0.0525083 -0.0652488" quat="0.579227 0.40558 -0.405579 0.579229" type="mesh" contype="0" conaffinity="0" group="1" density="0" rgba="0.933333 0.933333 0.933333 1" mesh="right_hip_roll_visual" />
          <body name="right_hip_yaw" pos="0 -0.0068404 -0.0187939" quat="0.579227 0.40558 -0.405579 0.579229">
            <inertial pos="0.00130421 2.35733e-05 -0.237299" quat="0.705202 0.0179505 0.0178928 0.708554" mass="2.08959" diaginertia="0.0118687 0.0116438 0.00259372" />
            <joint name="right_hip_yaw" pos="0 0 0" axis="0 0 1" range="-1.5708 1.5708" actuatorfrcrange="-97 97" frictionloss="0.1" armature="0.03" />
            <geom pos="0.00130421 2.35733e-05 -0.237299" quat="1 0 0 0" type="mesh" contype="0" conaffinity="0" group="1" density="0" rgba="0.933333 0.933333 0.933333 1" mesh="right_hip_yaw_visual" />
            <body name="right_knee_pitch" pos="-0.01 0 -0.33" quat="0.707105 -0.707108 0 0">
              <inertial pos="-0.0048642 0.0372186 0.000224747" quat="0.699331 0.706571 0.0768834 0.0760411" mass="0.435358" diaginertia="0.000927922 0.000714681 0.000610854" />
              <joint name="right_knee_pitch" pos="0 0 0" axis="0 0 1" range="0 2.35619" actuatorfrcrange="-97 97" frictionloss="0.1" armature="0.03" />
              <geom size="0.045 0.08" pos="-0.01 0.17 0" quat="0.499998 0.5 0.5 -0.500002" type="capsule" />
              <geom pos="-0.0048642 0.0372186 0.000224747" quat="0.707105 0.707108 0 0" type="mesh" contype="0" conaffinity="0" group="1" density="0" rgba="0.933333 0.933333 0.933333 1" mesh="right_knee_pitch_visual" />
              <body name="right_ankle_yaw" pos="-0.015 0 0" quat="0.707105 0.707108 0 0">
                <inertial pos="-0.00304908 -0.0015054 -0.185348" quat="0.690449 -0.00753269 -0.0099569 0.723273" mass="1.43169" diaginertia="0.00768644 0.00763447 0.00114897" />
                <joint name="right_ankle_yaw" pos="0 0 0" axis="0 0 1" range="-0.785398 0.785398" actuatorfrcrange="-27 27" frictionloss="0.1" armature="0.01" />
                <geom pos="-0.00304908 -0.0015054 -0.185348" quat="1 0 0 0" type="mesh" contype="0" conaffinity="0" group="1" density="0" rgba="0.933333 0.933333 0.933333 1" mesh="right_ankle_yaw_visual" />
                <body name="right_ankle_pitch" pos="0.01 0 -0.34" quat="0.707105 -0.707108 0 0">
                  <inertial pos="-0.00384209 0.0297371 3.1396e-08" quat="0.611225 0.355531 -0.611226 0.355534" mass="0.184118" diaginertia="0.00013275 0.000107104 6.80202e-05" />
                  <joint name="right_ankle_pitch" pos="0 0 0" axis="0 0 1" range="-0.523599 0.872665" actuatorfrcrange="-27 27" frictionloss="0.1" armature="0.01" />
                  <geom pos="-0.00384209 0.0297371 3.1396e-08" quat="0.707105 0.707108 0 0" type="mesh" contype="0" conaffinity="0" group="1" density="0" rgba="0.933333 0.933333 0.933333 1" mesh="right_ankle_pitch_visual" />
                  <body name="right_foot" pos="0 0.04 0" quat="0.707105 0 0.707108 0">
                    <inertial pos="-0.0012494 0.0227876 0.039804" quat="0.994259 -0.101477 -0.026289 -0.021469" mass="1.20654" diaginertia="0.00367661 0.00336341 0.00122719" />
                    <joint name="right_ankle_roll" pos="0 0 0" axis="0 0 1" range="-0.349066 0.349066" actuatorfrcrange="-5.5 5.5" frictionloss="0.1" armature="0.001" />
                    <geom size="0.0325 0.06 0.015" pos="0 0.08 0.015" quat="0.707105 0.707108 0 0" type="box" />
                    <geom size="0.035 0.025 0.015" pos="0 0.07 0.11" quat="0.573577 0.819151 0 0" type="box" />
                    <geom pos="-0.0012494 0.0227876 0.039804" quat="0.499998 0.5 -0.5 0.500002" type="mesh" contype="0" conaffinity="0" group="1" density="0" rgba="0.933333 0.933333 0.933333 1" mesh="right_foot_visual" />
                  </body>
                </body>
              </body>
            </body>
          </body>
        </body>
      </body>
    </body>
  </worldbody>
<actuator><motor name="left_hip_pitch" joint="left_hip_pitch" forcerange="-97.0 97.0" /><motor name="left_hip_roll" joint="left_hip_roll" forcerange="-97.0 97.0" /><motor name="left_hip_yaw" joint="left_hip_yaw" forcerange="-97.0 97.0" /><motor name="left_knee_pitch" joint="left_knee_pitch" forcerange="-97.0 97.0" /><motor name="left_ankle_yaw" joint="left_ankle_yaw" forcerange="-27.0 27.0" /><motor name="left_ankle_pitch" joint="left_ankle_pitch" forcerange="-27.0 27.0" /><motor name="left_ankle_roll" joint="left_ankle_roll" forcerange="-5.5 5.5" /><motor name="right_hip_pitch" joint="right_hip_pitch" forcerange="-97.0 97.0" /><motor name="right_hip_roll" joint="right_hip_roll" forcerange="-97.0 97.0" /><motor name="right_hip_yaw" joint="right_hip_yaw" forcerange="-97.0 97.0" /><motor name="right_knee_pitch" joint="right_knee_pitch" forcerange="-97.0 97.0" /><motor name="right_ankle_yaw" joint="right_ankle_yaw" forcerange="-27.0 27.0" /><motor name="right_ankle_pitch" joint="right_ankle_pitch" forcerange="-27.0 27.0" /><motor name="right_ankle_roll" joint="right_ankle_roll" forcerange="-5.5 5.5" /></actuator></mujoco>