<?xml version='1.0' encoding='utf-8'?>
<mujoco model="lite_biped">
  <!-- GENERATED by robot_assets from Onshape CAD. Do not edit by hand. Regenerate: robot-assets-generate lite_biped -->
  <compiler angle="radian" meshdir="../meshes/visual/" />

  <option timestep="0.005" integrator="implicitfast" solver="Newton" cone="pyramidal" impratio="1" iterations="10" ls_iterations="20" /><asset>
    <mesh name="pelvis_visual" content_type="model/stl" file="pelvis_visual.stl" />
    <mesh name="left_hip_pitch_visual" content_type="model/stl" file="left_hip_pitch_visual.stl" />
    <mesh name="left_hip_roll_visual" content_type="model/stl" file="left_hip_roll_visual.stl" />
    <mesh name="left_hip_yaw_visual" content_type="model/stl" file="left_hip_yaw_visual.stl" />
    <mesh name="left_knee_pitch_visual" content_type="model/stl" file="left_knee_pitch_visual.stl" />
    <mesh name="left_ankle_yaw_visual" content_type="model/stl" file="left_ankle_yaw_visual.stl" />
    <mesh name="left_ankle_pitch_visual" content_type="model/stl" file="left_ankle_pitch_visual.stl" />
    <mesh name="left_foot_visual" content_type="model/stl" file="left_foot_visual.stl" />
    <mesh name="right_hip_pitch_visual" content_type="model/stl" file="right_hip_pitch_visual.stl" />
    <mesh name="right_hip_roll_visual" content_type="model/stl" file="right_hip_roll_visual.stl" />
    <mesh name="right_hip_yaw_visual" content_type="model/stl" file="right_hip_yaw_visual.stl" />
    <mesh name="right_knee_pitch_visual" content_type="model/stl" file="right_knee_pitch_visual.stl" />
    <mesh name="right_ankle_yaw_visual" content_type="model/stl" file="right_ankle_yaw_visual.stl" />
    <mesh name="right_ankle_pitch_visual" content_type="model/stl" file="right_ankle_pitch_visual.stl" />
    <mesh name="right_foot_visual" content_type="model/stl" file="right_foot_visual.stl" />
  </asset>

  <worldbody>
    <body name="pelvis">
      <joint name="floating_base_joint" type="free" limited="false" actuatorfrclimited="false" /><site name="imu_site" pos="0.0 0.0 0.08" /><inertial pos="0.0137049 6.97587e-07 0.0692011" quat="0.999864 -1.34288e-05 0.0164944 1.28012e-05" mass="2.1" diaginertia="0.00988318 0.00823366 0.0063777" />
      <geom pos="0.0137049 6.97587e-07 0.0692011" type="mesh" contype="0" conaffinity="0" group="1" density="0" rgba="0.933333 0.933333 0.933333 1" mesh="pelvis_visual" />
      <body name="imu" pos="0 0 0.08">
        <inertial pos="0 0 0" mass="1e-09" diaginertia="0 0 0" />
      </body>
      <body name="left_hip_pitch" pos="0.02 0.07 0" quat="0.642787 -0.766045 0 0">
        <inertial pos="-0.0114774 0.00418673 0.0187959" quat="0.143691 0.579874 -0.102327 0.795379" mass="0.18" diaginertia="0.000298425 0.00023209 0.000171935" />
        <joint name="left_hip_pitch" pos="0 0 0" axis="0 0 1" range="-2.35619 0.785398" actuatorfrcrange="-36 36" frictionloss="0.1" armature="0.008" />
        <geom pos="-0.0114774 0.00418673 0.0187959" quat="0.642787 0.766045 0 0" type="mesh" contype="0" conaffinity="0" group="1" density="0" rgba="0.933333 0.933333 0.933333 1" mesh="left_hip_pitch_visual" />
        <body name="left_hip_roll" quat="0.683013 0.183012 0.704417 -0.0616252">
          <inertial pos="-4.8952e-08 0.0525082 -0.0652484" quat="0.382435 0.594774 -0.59476 0.382424" mass="0.93" diaginertia="0.00285203 0.00263146 0.00112675" />
          <joint name="left_hip_roll" pos="0 0 0" axis="0 0 1" range="-0.349066 1.5708" actuatorfrcrange="-36 36" frictionloss="0.1" armature="0.008" />
          <geom size="0.05 0.075" pos="0 0.181098 -0.0871979" quat="0.819152 0.573576 0 0" type="capsule" condim="1" />
          <geom pos="-4.8952e-08 0.0525082 -0.0652484" quat="0.579227 0.40558 -0.405579 0.579229" type="mesh" contype="0" conaffinity="0" group="1" density="0" rgba="0.933333 0.933333 0.933333 1" mesh="left_hip_roll_visual" />
          <body name="left_hip_yaw" pos="0 -0.0068404 -0.0187939" quat="0.579227 0.40558 -0.405579 0.579229">
            <inertial pos="0.00130442 -2.2783e-05 -0.237299" quat="0.708576 0.0178897 0.0179547 0.705179" mass="1.54" diaginertia="0.00874707 0.00858135 0.00191153" />
            <joint name="left_hip_yaw" pos="0 0 0" axis="0 0 1" range="-1.5708 1.5708" actuatorfrcrange="-17 17" frictionloss="0.1" armature="0.005" />
            <geom pos="0.00130442 -2.2783e-05 -0.237299" quat="1 0 0 0" type="mesh" contype="0" conaffinity="0" group="1" density="0" rgba="0.933333 0.933333 0.933333 1" mesh="left_hip_yaw_visual" />
            <body name="left_knee_pitch" pos="-0.01 0 -0.33" quat="0.707105 -0.707108 0 0">
              <inertial pos="-0.00486713 0.0372163 -0.000224083" quat="0.706661 0.699245 0.0760196 0.0768538" mass="0.23" diaginertia="0.000490196 0.000377566 0.000322724" />
              <joint name="left_knee_pitch" pos="0 0 0" axis="0 0 1" range="0 2.35619" actuatorfrcrange="-36 36" frictionloss="0.1" armature="0.008" />
              <geom size="0.045 0.06" pos="-0.015 0.19 0" quat="0.499998 0.5 0.5 -0.500002" type="capsule" condim="1" />
              <geom pos="-0.00486713 0.0372163 -0.000224083" quat="0.707105 0.707108 0 0" type="mesh" contype="0" conaffinity="0" group="1" density="0" rgba="0.933333 0.933333 0.933333 1" mesh="left_knee_pitch_visual" />
              <body name="left_ankle_yaw" pos="-0.015 0 0" quat="0.707105 0.707108 0 0">
                <inertial pos="-0.00304992 0.00150525 -0.18535" quat="0.723191 -0.0099567 -0.00753121 0.690535" mass="1.03" diaginertia="0.00552984 0.00549241 0.000826604" />
                <joint name="left_ankle_yaw" pos="0 0 0" axis="0 0 1" range="-1.5708 1.5708" actuatorfrcrange="-14 14" frictionloss="0.1" armature="0.002" />
                <geom pos="-0.00304992 0.00150525 -0.18535" quat="1 0 0 0" type="mesh" contype="0" conaffinity="0" group="1" density="0" rgba="0.933333 0.933333 0.933333 1" mesh="left_ankle_yaw_visual" />
                <body name="left_ankle_pitch" pos="0.01 0 -0.34" quat="0.707105 -0.707108 0 0">
                  <inertial pos="-0.00384209 0.0297371 3.1356e-08" quat="0.611225 0.355531 -0.611226 0.355534" mass="0.34" diaginertia="0.000245142 0.000197784 0.000125609" />
                  <joint name="left_ankle_pitch" pos="0 0 0" axis="0 0 1" range="-0.523599 0.872665" actuatorfrcrange="-14 14" frictionloss="0.1" armature="0.002" />
                  <geom pos="-0.00384209 0.0297371 3.1356e-08" quat="0.707105 0.707108 0 0" type="mesh" contype="0" conaffinity="0" group="1" density="0" rgba="0.933333 0.933333 0.933333 1" mesh="left_ankle_pitch_visual" />
                  <body name="left_foot" pos="0 0.04 0" quat="0.707105 0 0.707108 0">
                    <inertial pos="0.00124938 0.0227876 0.0398042" quat="0.994259 -0.101477 0.0262886 0.021467" mass="0.44" diaginertia="0.00134078 0.00122657 0.000447531" />
                    <joint name="left_ankle_roll" pos="0 0 0" axis="0 0 1" range="-0.349066 0.349066" actuatorfrcrange="-5.5 5.5" frictionloss="0.1" armature="0.001" />
                    <geom size="0.0325 0.06 0.015" pos="0 0.05 0.015" quat="0.707105 0.707108 0 0" type="box" condim="3" friction="0.6 0.005 0.0001" priority="1" />
                    <geom size="0.035 0.025 0.015" pos="0 0.04 0.11" quat="0.573577 0.819151 0 0" type="box" condim="3" friction="0.6 0.005 0.0001" priority="1" />
                    <geom pos="0.00124938 0.0227876 0.0398042" quat="0.499998 0.5 -0.5 0.500002" type="mesh" contype="0" conaffinity="0" group="1" density="0" rgba="0.933333 0.933333 0.933333 1" mesh="left_foot_visual" />
                  </body>
                </body>
              </body>
            </body>
          </body>
        </body>
      </body>
      <body name="right_hip_pitch" pos="0.02 -0.07 0" quat="0.766046 -0.642786 0 0">
        <inertial pos="-0.0114771 0.00418737 -0.0187964" quat="0.10235 0.795381 -0.143679 0.579871" mass="0.18" diaginertia="0.000298423 0.0002321 0.000171928" />
        <joint name="right_hip_pitch" pos="0 0 0" axis="0 0 1" range="-2.35619 0.785398" actuatorfrcrange="-36 36" frictionloss="0.1" armature="0.008" />
        <geom pos="-0.0114771 0.00418737 -0.0187964" quat="0.766046 0.642786 0 0" type="mesh" contype="0" conaffinity="0" group="1" density="0" rgba="0.933333 0.933333 0.933333 1" mesh="right_hip_pitch_visual" />
        <body name="right_hip_roll" quat="0.704416 0.0616286 0.683012 -0.183015">
          <inertial pos="2.6715e-08 0.0525085 -0.0652483" quat="0.382434 0.594774 -0.594759 0.382426" mass="0.93" diaginertia="0.00285206 0.00263147 0.00112674" />
          <joint name="right_hip_roll" pos="0 0 0" axis="0 0 1" range="-1.5708 0.349066" actuatorfrcrange="-36 36" frictionloss="0.1" armature="0.008" />
          <geom size="0.05 0.075" pos="1.40064e-07 0.181098 -0.0871974" quat="0.819152 0.573576 0 0" type="capsule" condim="1" />
          <geom pos="2.6715e-08 0.0525085 -0.0652483" quat="0.579227 0.40558 -0.405579 0.579229" type="mesh" contype="0" conaffinity="0" group="1" density="0" rgba="0.933333 0.933333 0.933333 1" mesh="right_hip_roll_visual" />
          <body name="right_hip_yaw" pos="0 -0.0068404 -0.0187939" quat="0.579227 0.40558 -0.405579 0.579229">
            <inertial pos="0.00130421 2.35733e-05 -0.237299" quat="0.705202 0.0179505 0.0178929 0.708554" mass="1.54" diaginertia="0.00874705 0.00858133 0.00191154" />
            <joint name="right_hip_yaw" pos="0 0 0" axis="0 0 1" range="-1.5708 1.5708" actuatorfrcrange="-17 17" frictionloss="0.1" armature="0.005" />
            <geom pos="0.00130421 2.35733e-05 -0.237299" quat="1 0 0 0" type="mesh" contype="0" conaffinity="0" group="1" density="0" rgba="0.933333 0.933333 0.933333 1" mesh="right_hip_yaw_visual" />
            <body name="right_knee_pitch" pos="-0.01 0 -0.33" quat="0.707105 -0.707108 0 0">
              <inertial pos="-0.0048642 0.0372186 0.000224747" quat="0.699331 0.706571 0.0768833 0.076041" mass="0.23" diaginertia="0.000490222 0.000377567 0.000322714" />
              <joint name="right_knee_pitch" pos="0 0 0" axis="0 0 1" range="0 2.35619" actuatorfrcrange="-36 36" frictionloss="0.1" armature="0.008" />
              <geom size="0.045 0.06" pos="-0.015 0.19 0" quat="0.499998 0.5 0.5 -0.500002" type="capsule" condim="1" />
              <geom pos="-0.0048642 0.0372186 0.000224747" quat="0.707105 0.707108 0 0" type="mesh" contype="0" conaffinity="0" group="1" density="0" rgba="0.933333 0.933333 0.933333 1" mesh="right_knee_pitch_visual" />
              <body name="right_ankle_yaw" pos="-0.015 0 0" quat="0.707105 0.707108 0 0">
                <inertial pos="-0.00304908 -0.0015054 -0.185348" quat="0.690451 -0.00753267 -0.00995694 0.723271" mass="1.03" diaginertia="0.00552984 0.00549244 0.000826601" />
                <joint name="right_ankle_yaw" pos="0 0 0" axis="0 0 1" range="-1.5708 1.5708" actuatorfrcrange="-14 14" frictionloss="0.1" armature="0.002" />
                <geom pos="-0.00304908 -0.0015054 -0.185348" quat="1 0 0 0" type="mesh" contype="0" conaffinity="0" group="1" density="0" rgba="0.933333 0.933333 0.933333 1" mesh="right_ankle_yaw_visual" />
                <body name="right_ankle_pitch" pos="0.01 0 -0.34" quat="0.707105 -0.707108 0 0">
                  <inertial pos="-0.00384209 0.0297371 3.1396e-08" quat="0.611225 0.355531 -0.611226 0.355534" mass="0.34" diaginertia="0.000245142 0.000197784 0.000125609" />
                  <joint name="right_ankle_pitch" pos="0 0 0" axis="0 0 1" range="-0.523599 0.872665" actuatorfrcrange="-14 14" frictionloss="0.1" armature="0.002" />
                  <geom pos="-0.00384209 0.0297371 3.1396e-08" quat="0.707105 0.707108 0 0" type="mesh" contype="0" conaffinity="0" group="1" density="0" rgba="0.933333 0.933333 0.933333 1" mesh="right_ankle_pitch_visual" />
                  <body name="right_foot" pos="0 0.04 0" quat="0.707105 0 0.707108 0">
                    <inertial pos="-0.0012494 0.0227876 0.039804" quat="0.994259 -0.101477 -0.0262888 -0.0214685" mass="0.44" diaginertia="0.00134078 0.00122657 0.000447531" />
                    <joint name="right_ankle_roll" pos="0 0 0" axis="0 0 1" range="-0.349066 0.349066" actuatorfrcrange="-5.5 5.5" frictionloss="0.1" armature="0.001" />
                    <geom size="0.0325 0.06 0.015" pos="0 0.05 0.015" quat="0.707105 0.707108 0 0" type="box" condim="3" friction="0.6 0.005 0.0001" priority="1" />
                    <geom size="0.035 0.025 0.015" pos="0 0.04 0.11" quat="0.573577 0.819151 0 0" type="box" condim="3" friction="0.6 0.005 0.0001" priority="1" />
                    <geom pos="-0.0012494 0.0227876 0.039804" quat="0.499998 0.5 -0.5 0.500002" type="mesh" contype="0" conaffinity="0" group="1" density="0" rgba="0.933333 0.933333 0.933333 1" mesh="right_foot_visual" />
                  </body>
                </body>
              </body>
            </body>
          </body>
        </body>
      </body>
    </body>
  </worldbody>
<sensor><framequat name="base_quat" objtype="site" objname="imu_site" /><gyro name="base_gyro" site="imu_site" /><accelerometer name="base_accel" site="imu_site" /><velocimeter name="base_vel" site="imu_site" /><framepos name="base_pos" objtype="site" objname="imu_site" /></sensor><actuator><motor name="left_hip_pitch" joint="left_hip_pitch" forcerange="-36.0 36.0" /><motor name="left_hip_roll" joint="left_hip_roll" forcerange="-36.0 36.0" /><motor name="left_hip_yaw" joint="left_hip_yaw" forcerange="-17.0 17.0" /><motor name="left_knee_pitch" joint="left_knee_pitch" forcerange="-36.0 36.0" /><motor name="left_ankle_yaw" joint="left_ankle_yaw" forcerange="-14.0 14.0" /><motor name="left_ankle_pitch" joint="left_ankle_pitch" forcerange="-14.0 14.0" /><motor name="left_ankle_roll" joint="left_ankle_roll" forcerange="-5.5 5.5" /><motor name="right_hip_pitch" joint="right_hip_pitch" forcerange="-36.0 36.0" /><motor name="right_hip_roll" joint="right_hip_roll" forcerange="-36.0 36.0" /><motor name="right_hip_yaw" joint="right_hip_yaw" forcerange="-17.0 17.0" /><motor name="right_knee_pitch" joint="right_knee_pitch" forcerange="-36.0 36.0" /><motor name="right_ankle_yaw" joint="right_ankle_yaw" forcerange="-14.0 14.0" /><motor name="right_ankle_pitch" joint="right_ankle_pitch" forcerange="-14.0 14.0" /><motor name="right_ankle_roll" joint="right_ankle_roll" forcerange="-5.5 5.5" /></actuator></mujoco>