<?xml version='1.0' encoding='utf-8'?>
<robot name="lite">
  <!-- GENERATED by robot_assets from Onshape CAD. Do not edit by hand. Regenerate: robot-assets-generate lite -->
  <link name="pelvis">
    <inertial>
      <origin xyz="0.0135183 5.78646e-07 0.0691358" rpy="0 0 0" />
      <mass value="3.97182" />
      <inertia ixx="0.0186861" ixy="7.2433e-08" ixz="-0.000228382" iyy="0.015546" iyz="-9.5463e-08" izz="0.0121371" />
    </inertial>
    <!-- Part pelvis_parts -->
    <collision>
      <origin xyz="0.02 0 -0" rpy="1.5708 1.5708 0" />
      <geometry>
        <cylinder length="0.16" radius="0.05" />
      </geometry>
    </collision>
    <visual>
      <origin xyz="0.0135183 5.78646e-07 0.0691358" rpy="0 -0 0" />
      <geometry>
        <mesh filename="../meshes/visual/pelvis_visual.stl" />
      </geometry>
      <material name="pelvis_parts_material">
        <color rgba="0.933333 0.933333 0.933333 1" />
      </material>
    </visual>
  </link>
  <!-- Link left_hip_pitch -->
  <link name="left_hip_pitch">
    <inertial>
      <origin xyz="-0.0114774 0.00418673 0.0187959" rpy="0 0 0" />
      <mass value="0.619442" />
      <inertia ixx="0.000652303" ixy="5.37205e-05" ixz="-0.00011886" iyy="0.000778993" iyz="4.47861e-05" izz="0.000986073" />
    </inertial>
    <!-- Part left_hip_pitch_parts -->
    <visual>
      <origin xyz="-0.0114774 0.00418673 0.0187959" rpy="1.74533 0 -0" />
      <geometry>
        <mesh filename="../meshes/visual/left_hip_pitch_visual.stl" />
      </geometry>
      <material name="left_hip_pitch_parts_material">
        <color rgba="0.933333 0.933333 0.933333 1" />
      </material>
    </visual>
  </link>
  <!-- Link left_hip_roll -->
  <link name="left_hip_roll">
    <inertial>
      <origin xyz="-4.8952e-08 0.0525082 -0.0652484" rpy="0 0 0" />
      <mass value="1.30369" />
      <inertia ixx="0.00368883" ixy="-7.197e-09" ixz="4.838e-09" iyy="0.00199601" iyz="-0.000913168" izz="0.00358153" />
    </inertial>
    <!-- Part left_hip_roll_parts -->
    <collision>
      <origin xyz="0 0.181098 -0.0871979" rpy="1.22173 -0 0" />
      <geometry>
        <cylinder length="0.15" radius="0.05" />
      </geometry>
    </collision>
    <visual>
      <origin xyz="-4.8952e-08 0.0525082 -0.0652484" rpy="0 -1.22173 1.5708" />
      <geometry>
        <mesh filename="../meshes/visual/left_hip_roll_visual.stl" />
      </geometry>
      <material name="left_hip_roll_parts_material">
        <color rgba="0.933333 0.933333 0.933333 1" />
      </material>
    </visual>
  </link>
  <!-- Link left_hip_yaw -->
  <link name="left_hip_yaw">
    <inertial>
      <origin xyz="0.00130442 -2.2783e-05 -0.237299" rpy="0 0 0" />
      <mass value="2.08958" />
      <inertia ixx="0.0116205" ixy="1.09303e-06" ixz="-0.000458028" iyy="0.0118686" iyz="2.21073e-07" izz="0.00261694" />
    </inertial>
    <!-- Part left_hip_yaw_parts -->
    <visual>
      <origin xyz="0.00130442 -2.2783e-05 -0.237299" rpy="-0 0 -0" />
      <geometry>
        <mesh filename="../meshes/visual/left_hip_yaw_visual.stl" />
      </geometry>
      <material name="left_hip_yaw_parts_material">
        <color rgba="0.933333 0.933333 0.933333 1" />
      </material>
    </visual>
  </link>
  <!-- Link left_knee_pitch -->
  <link name="left_knee_pitch">
    <inertial>
      <origin xyz="-0.00486713 0.0372163 -0.000224083" rpy="0 0 0" />
      <mass value="0.435399" />
      <inertia ixx="0.000913317" ixy="6.65453e-05" ixz="-2.2735e-07" iyy="0.000625586" iyz="1.07178e-06" izz="0.000714736" />
    </inertial>
    <!-- Part left_knee_pitch_parts -->
    <collision>
      <origin xyz="-0.015 0.19 0" rpy="1.5708 1.5708 0" />
      <geometry>
        <cylinder length="0.12" radius="0.045" />
      </geometry>
    </collision>
    <visual>
      <origin xyz="-0.00486713 0.0372163 -0.000224083" rpy="1.5708 0 0" />
      <geometry>
        <mesh filename="../meshes/visual/left_knee_pitch_visual.stl" />
      </geometry>
      <material name="left_knee_pitch_parts_material">
        <color rgba="0.933333 0.933333 0.933333 1" />
      </material>
    </visual>
  </link>
  <!-- Link left_ankle_yaw -->
  <link name="left_ankle_yaw">
    <inertial>
      <origin xyz="-0.00304992 0.00150525 -0.18535" rpy="0 0 0" />
      <mass value="1.43174" />
      <inertia ixx="0.00763083" ixy="3.0411e-06" ixz="0.000159775" iyy="0.00768647" iyz="-2.6083e-05" izz="0.00115305" />
    </inertial>
    <!-- Part left_ankle_yaw_parts -->
    <visual>
      <origin xyz="-0.00304992 0.00150525 -0.18535" rpy="-0 0 -0" />
      <geometry>
        <mesh filename="../meshes/visual/left_ankle_yaw_visual.stl" />
      </geometry>
      <material name="left_ankle_yaw_parts_material">
        <color rgba="0.933333 0.933333 0.933333 1" />
      </material>
    </visual>
  </link>
  <!-- Link left_ankle_pitch -->
  <link name="left_ankle_pitch">
    <inertial>
      <origin xyz="-0.00384209 0.0297371 3.1356e-08" rpy="0 0 0" />
      <mass value="0.184118" />
      <inertia ixx="9.75514e-05" ixy="-1.6796e-05" ixz="-4.2e-11" iyy="7.7573e-05" iyz="1.44e-10" izz="0.00013275" />
    </inertial>
    <!-- Part left_ankle_pitch_parts -->
    <visual>
      <origin xyz="-0.00384209 0.0297371 3.1356e-08" rpy="1.5708 -0 -0" />
      <geometry>
        <mesh filename="../meshes/visual/left_ankle_pitch_visual.stl" />
      </geometry>
      <material name="left_ankle_pitch_parts_material">
        <color rgba="0.933333 0.933333 0.933333 1" />
      </material>
    </visual>
  </link>
  <!-- Link left_foot -->
  <link name="left_foot">
    <inertial>
      <origin xyz="0.00124938 0.0227876 0.0398042" rpy="0 0 0" />
      <mass value="1.20654" />
      <inertia ixx="0.00367026" ixy="-9.09996e-06" ixz="-0.000117811" iyy="0.00327589" iyz="-0.000424612" izz="0.00132106" />
    </inertial>
    <!-- Part left_foot_parts -->
    <collision>
      <origin xyz="0 0.05 0.015" rpy="1.5708 0 0" />
      <geometry>
        <box size="0.065 0.12 0.03" />
      </geometry>
    </collision>
    <collision>
      <origin xyz="0 0.04 0.11" rpy="1.91986 0 0" />
      <geometry>
        <box size="0.07 0.05 0.03" />
      </geometry>
    </collision>
    <visual>
      <origin xyz="0.00124938 0.0227876 0.0398042" rpy="1.5708 -1.5708 0" />
      <geometry>
        <mesh filename="../meshes/visual/left_foot_visual.stl" />
      </geometry>
      <material name="left_foot_parts_material">
        <color rgba="0.933333 0.933333 0.933333 1" />
      </material>
    </visual>
  </link>
  <!-- Joint from left_ankle_pitch to left_foot -->
  <joint name="left_ankle_roll" type="revolute">
    <origin xyz="-0 0.04 0" rpy="0 1.5708 0" />
    <parent link="left_ankle_pitch" />
    <child link="left_foot" />
    <axis xyz="0 0 1" />
    <limit effort="5.5" velocity="100" lower="-0.349066" upper="0.349066" />
    <joint_properties friction="0.1" />
  </joint>
  <!-- Joint from left_ankle_yaw to left_ankle_pitch -->
  <joint name="left_ankle_pitch" type="revolute">
    <origin xyz="0.01 -0 -0.34" rpy="-1.5708 0 -0" />
    <parent link="left_ankle_yaw" />
    <child link="left_ankle_pitch" />
    <axis xyz="0 0 1" />
    <limit effort="14.0" velocity="100" lower="-0.523599" upper="0.872665" />
    <joint_properties friction="0.1" />
  </joint>
  <!-- Joint from left_knee_pitch to left_ankle_yaw -->
  <joint name="left_ankle_yaw" type="revolute">
    <origin xyz="-0.015 0 0" rpy="1.5708 0 -0" />
    <parent link="left_knee_pitch" />
    <child link="left_ankle_yaw" />
    <axis xyz="0 0 1" />
    <limit effort="14.0" velocity="100" lower="-0.785398" upper="0.785398" />
    <joint_properties friction="0.1" />
  </joint>
  <!-- Joint from left_hip_yaw to left_knee_pitch -->
  <joint name="left_knee_pitch" type="revolute">
    <origin xyz="-0.01 0 -0.33" rpy="-1.5708 0 0" />
    <parent link="left_hip_yaw" />
    <child link="left_knee_pitch" />
    <axis xyz="0 0 1" />
    <limit effort="36.0" velocity="100" lower="0" upper="2.35619" />
    <joint_properties friction="0.1" />
  </joint>
  <!-- Joint from left_hip_roll to left_hip_yaw -->
  <joint name="left_hip_yaw" type="revolute">
    <origin xyz="0 -0.0068404 -0.0187939" rpy="0 -1.22173 1.5708" />
    <parent link="left_hip_roll" />
    <child link="left_hip_yaw" />
    <axis xyz="0 0 1" />
    <limit effort="17.0" velocity="100" lower="-1.5708" upper="1.5708" />
    <joint_properties friction="0.1" />
  </joint>
  <!-- Joint from left_hip_pitch to left_hip_roll -->
  <joint name="left_hip_roll" type="revolute">
    <origin xyz="-0 0 -0" rpy="1.91986 1.39626 1.5708" />
    <parent link="left_hip_pitch" />
    <child link="left_hip_roll" />
    <axis xyz="0 0 1" />
    <limit effort="36.0" velocity="100" lower="-0.349066" upper="1.5708" />
    <joint_properties friction="0.1" />
  </joint>
  <!-- Joint from pelvis to left_hip_pitch -->
  <joint name="left_hip_pitch" type="revolute">
    <origin xyz="0.02 0.07 0" rpy="-1.74533 0 0" />
    <parent link="pelvis" />
    <child link="left_hip_pitch" />
    <axis xyz="0 0 1" />
    <limit effort="36.0" velocity="100" lower="-2.35619" upper="0.785398" />
    <joint_properties friction="0.1" />
  </joint>
  <!-- Link right_hip_pitch -->
  <link name="right_hip_pitch">
    <inertial>
      <origin xyz="-0.0114771 0.00418737 -0.0187964" rpy="0 0 0" />
      <mass value="0.619423" />
      <inertia ixx="0.000652275" ixy="5.37438e-05" ixz="0.000118863" iyy="0.000778995" iyz="-4.4778e-05" izz="0.000986036" />
    </inertial>
    <!-- Part right_hip_pitch_parts -->
    <visual>
      <origin xyz="-0.0114771 0.00418737 -0.0187964" rpy="1.39626 0 -0" />
      <geometry>
        <mesh filename="../meshes/visual/right_hip_pitch_visual.stl" />
      </geometry>
      <material name="right_hip_pitch_parts_material">
        <color rgba="0.933333 0.933333 0.933333 1" />
      </material>
    </visual>
  </link>
  <!-- Link right_hip_roll -->
  <link name="right_hip_roll">
    <inertial>
      <origin xyz="-1.13349e-07 0.0525083 -0.0652488" rpy="0 0 0" />
      <mass value="1.30368" />
      <inertia ixx="0.0036888" ixy="3.8e-10" ixz="8.521e-09" iyy="0.00199598" iyz="-0.000913166" izz="0.0035815" />
    </inertial>
    <!-- Part right_hip_roll_parts -->
    <collision>
      <origin xyz="-0 0.181098 -0.0871979" rpy="1.22173 0 0" />
      <geometry>
        <cylinder length="0.15" radius="0.05" />
      </geometry>
    </collision>
    <visual>
      <origin xyz="-1.13349e-07 0.0525083 -0.0652488" rpy="0 -1.22173 1.5708" />
      <geometry>
        <mesh filename="../meshes/visual/right_hip_roll_visual.stl" />
      </geometry>
      <material name="right_hip_roll_parts_material">
        <color rgba="0.933333 0.933333 0.933333 1" />
      </material>
    </visual>
  </link>
  <!-- Link right_hip_yaw -->
  <link name="right_hip_yaw">
    <inertial>
      <origin xyz="0.00130421 2.35733e-05 -0.237299" rpy="0 0 0" />
      <mass value="2.08959" />
      <inertia ixx="0.0116206" ixy="-1.08279e-06" ixz="-0.000458016" iyy="0.0118687" iyz="-3.03522e-07" izz="0.00261696" />
    </inertial>
    <!-- Part right_hip_yaw_parts -->
    <visual>
      <origin xyz="0.00130421 2.35733e-05 -0.237299" rpy="0 0 0" />
      <geometry>
        <mesh filename="../meshes/visual/right_hip_yaw_visual.stl" />
      </geometry>
      <material name="right_hip_yaw_parts_material">
        <color rgba="0.933333 0.933333 0.933333 1" />
      </material>
    </visual>
  </link>
  <!-- Link right_knee_pitch -->
  <link name="right_knee_pitch">
    <inertial>
      <origin xyz="-0.0048642 0.0372186 0.000224747" rpy="0 0 0" />
      <mass value="0.435358" />
      <inertia ixx="0.000913266" ixy="6.65739e-05" ixz="2.14089e-07" iyy="0.000625521" iyz="-1.04876e-06" izz="0.00071467" />
    </inertial>
    <!-- Part right_knee_pitch_parts -->
    <collision>
      <origin xyz="-0.015 0.19 0" rpy="1.5708 1.5708 0" />
      <geometry>
        <cylinder length="0.12" radius="0.045" />
      </geometry>
    </collision>
    <visual>
      <origin xyz="-0.0048642 0.0372186 0.000224747" rpy="1.5708 -0 0" />
      <geometry>
        <mesh filename="../meshes/visual/right_knee_pitch_visual.stl" />
      </geometry>
      <material name="right_knee_pitch_parts_material">
        <color rgba="0.933333 0.933333 0.933333 1" />
      </material>
    </visual>
  </link>
  <!-- Link right_ankle_yaw -->
  <link name="right_ankle_yaw">
    <inertial>
      <origin xyz="-0.00304909 -0.00150539 -0.185348" rpy="0 0 0" />
      <mass value="1.43169" />
      <inertia ixx="0.00763064" ixy="-3.05072e-06" ixz="0.000159784" iyy="0.00768622" iyz="2.60897e-05" izz="0.00115301" />
    </inertial>
    <!-- Part right_ankle_yaw_parts -->
    <visual>
      <origin xyz="-0.00304909 -0.00150539 -0.185348" rpy="-0 0 0" />
      <geometry>
        <mesh filename="../meshes/visual/right_ankle_yaw_visual.stl" />
      </geometry>
      <material name="right_ankle_yaw_parts_material">
        <color rgba="0.933333 0.933333 0.933333 1" />
      </material>
    </visual>
  </link>
  <!-- Link right_ankle_pitch -->
  <link name="right_ankle_pitch">
    <inertial>
      <origin xyz="-0.00384209 0.0297371 3.1396e-08" rpy="0 0 0" />
      <mass value="0.184118" />
      <inertia ixx="9.75514e-05" ixy="-1.6796e-05" ixz="-4.2e-11" iyy="7.7573e-05" iyz="1.44e-10" izz="0.00013275" />
    </inertial>
    <!-- Part right_ankle_pitch_parts -->
    <visual>
      <origin xyz="-0.00384209 0.0297371 3.1396e-08" rpy="1.5708 -0 0" />
      <geometry>
        <mesh filename="../meshes/visual/right_ankle_pitch_visual.stl" />
      </geometry>
      <material name="right_ankle_pitch_parts_material">
        <color rgba="0.933333 0.933333 0.933333 1" />
      </material>
    </visual>
  </link>
  <!-- Link right_foot -->
  <link name="right_foot">
    <inertial>
      <origin xyz="-0.0012494 0.0227876 0.039804" rpy="0 0 0" />
      <mass value="1.20654" />
      <inertia ixx="0.00367026" ixy="9.09895e-06" ixz="0.000117812" iyy="0.00327589" iyz="-0.000424612" izz="0.00132106" />
    </inertial>
    <!-- Part right_foot_parts -->
    <collision>
      <origin xyz="0 0.05 0.015" rpy="1.5708 0 -0" />
      <geometry>
        <box size="0.065 0.12 0.03" />
      </geometry>
    </collision>
    <collision>
      <origin xyz="0 0.04 0.11" rpy="1.91986 0 -0" />
      <geometry>
        <box size="0.07 0.05 0.03" />
      </geometry>
    </collision>
    <visual>
      <origin xyz="-0.0012494 0.0227876 0.039804" rpy="1.5708 -1.5708 0" />
      <geometry>
        <mesh filename="../meshes/visual/right_foot_visual.stl" />
      </geometry>
      <material name="right_foot_parts_material">
        <color rgba="0.933333 0.933333 0.933333 1" />
      </material>
    </visual>
  </link>
  <!-- Joint from right_ankle_pitch to right_foot -->
  <joint name="right_ankle_roll" type="revolute">
    <origin xyz="0 0.04 0" rpy="0 1.5708 0" />
    <parent link="right_ankle_pitch" />
    <child link="right_foot" />
    <axis xyz="0 0 1" />
    <limit effort="5.5" velocity="100" lower="-0.349066" upper="0.349066" />
    <joint_properties friction="0.1" />
  </joint>
  <!-- Joint from right_ankle_yaw to right_ankle_pitch -->
  <joint name="right_ankle_pitch" type="revolute">
    <origin xyz="0.01 0 -0.34" rpy="-1.5708 -0 -0" />
    <parent link="right_ankle_yaw" />
    <child link="right_ankle_pitch" />
    <axis xyz="0 0 1" />
    <limit effort="14.0" velocity="100" lower="-0.523599" upper="0.872665" />
    <joint_properties friction="0.1" />
  </joint>
  <!-- Joint from right_knee_pitch to right_ankle_yaw -->
  <joint name="right_ankle_yaw" type="revolute">
    <origin xyz="-0.015 0 0" rpy="1.5708 -0 -0" />
    <parent link="right_knee_pitch" />
    <child link="right_ankle_yaw" />
    <axis xyz="0 0 1" />
    <limit effort="14.0" velocity="100" lower="-0.785398" upper="0.785398" />
    <joint_properties friction="0.1" />
  </joint>
  <!-- Joint from right_hip_yaw to right_knee_pitch -->
  <joint name="right_knee_pitch" type="revolute">
    <origin xyz="-0.01 -0 -0.33" rpy="-1.5708 0 -0" />
    <parent link="right_hip_yaw" />
    <child link="right_knee_pitch" />
    <axis xyz="0 0 1" />
    <limit effort="36.0" velocity="100" lower="0" upper="2.35619" />
    <joint_properties friction="0.1" />
  </joint>
  <!-- Joint from right_hip_roll to right_hip_yaw -->
  <joint name="right_hip_yaw" type="revolute">
    <origin xyz="0 -0.0068404 -0.0187939" rpy="0 -1.22173 1.5708" />
    <parent link="right_hip_roll" />
    <child link="right_hip_yaw" />
    <axis xyz="0 0 1" />
    <limit effort="17.0" velocity="100" lower="-1.5708" upper="1.5708" />
    <joint_properties friction="0.1" />
  </joint>
  <!-- Joint from right_hip_pitch to right_hip_roll -->
  <joint name="right_hip_roll" type="revolute">
    <origin xyz="0 -0 -0" rpy="-1.22173 1.39626 -1.5708" />
    <parent link="right_hip_pitch" />
    <child link="right_hip_roll" />
    <axis xyz="0 0 1" />
    <limit effort="36.0" velocity="100" lower="-1.5708" upper="0.349066" />
    <joint_properties friction="0.1" />
  </joint>
  <!-- Joint from pelvis to right_hip_pitch -->
  <joint name="right_hip_pitch" type="revolute">
    <origin xyz="0.02 -0.07 -0" rpy="-1.39626 -0 0" />
    <parent link="pelvis" />
    <child link="right_hip_pitch" />
    <axis xyz="0 0 1" />
    <limit effort="36.0" velocity="100" lower="-2.35619" upper="0.785398" />
    <joint_properties friction="0.1" />
  </joint>
  <!-- Link chest -->
  <link name="chest">
    <inertial>
      <origin xyz="-0.00852476 -8.0571e-08 0.178202" rpy="0 0 0" />
      <mass value="4.30714" />
      <inertia ixx="0.027397" ixy="1.54187e-07" ixz="0.00416783" iyy="0.0272965" iyz="6.06185e-07" izz="0.0103967" />
    </inertial>
    <!-- Part chest_parts -->
    <collision>
      <origin xyz="0.005 0 0.1" rpy="0.261799 0 -1.5708" />
      <geometry>
        <box size="0.08 0.1 0.18" />
      </geometry>
    </collision>
    <visual>
      <origin xyz="-0.00852476 -8.0571e-08 0.178202" rpy="-0 0 -0" />
      <geometry>
        <mesh filename="../meshes/visual/chest_visual.stl" />
      </geometry>
      <material name="chest_parts_material">
        <color rgba="0.933333 0.933333 0.933333 1" />
      </material>
    </visual>
  </link>
  <!-- Link left_shoulder_pitch -->
  <link name="left_shoulder_pitch">
    <inertial>
      <origin xyz="-6.27e-10 -0.00168619 -0.00682299" rpy="0 0 0" />
      <mass value="0.375" />
      <inertia ixx="0.000232695" ixy="7e-12" ixz="2e-12" iyy="0.000233203" iyz="-1.40823e-05" izz="0.000199827" />
    </inertial>
    <!-- Part left_shoulder_pitch_parts -->
    <visual>
      <origin xyz="-6.27e-10 -0.00168619 -0.00682299" rpy="1.39626 0 -0" />
      <geometry>
        <mesh filename="../meshes/visual/left_shoulder_pitch_visual.stl" />
      </geometry>
      <material name="left_shoulder_pitch_parts_material">
        <color rgba="0.933333 0.933333 0.933333 1" />
      </material>
    </visual>
  </link>
  <!-- Link left_shoulder_roll -->
  <link name="left_shoulder_roll">
    <inertial>
      <origin xyz="1.04497e-07 0.0788914 2.17586e-07" rpy="0 0 0" />
      <mass value="0.42" />
      <inertia ixx="0.000535467" ixy="-2.373e-09" ixz="5.049e-09" iyy="0.000208176" iyz="7.18e-09" izz="0.00050471" />
    </inertial>
    <!-- Part left_shoulder_roll_parts -->
    <visual>
      <origin xyz="1.04497e-07 0.0788914 2.17586e-07" rpy="0 -1.5708 0" />
      <geometry>
        <mesh filename="../meshes/visual/left_shoulder_roll_visual.stl" />
      </geometry>
      <material name="left_shoulder_roll_parts_material">
        <color rgba="0.392063 0.392063 0.392063 1" />
      </material>
    </visual>
  </link>
  <!-- Link left_shoulder_yaw -->
  <link name="left_shoulder_yaw">
    <inertial>
      <origin xyz="0.00503665 -3.0465e-08 -0.0550993" rpy="0 0 0" />
      <mass value="0.43" />
      <inertia ixx="0.000494513" ixy="-1.96e-10" ixz="4.80344e-05" iyy="0.000498656" iyz="9.95e-10" izz="0.000218184" />
    </inertial>
    <!-- Part left_shoulder_yaw_parts -->
    <collision>
      <origin xyz="0 -0 0.03" rpy="0 -0 -1.5708" />
      <geometry>
        <cylinder length="0.08" radius="0.03" />
      </geometry>
    </collision>
    <visual>
      <origin xyz="0.00503665 -3.0465e-08 -0.0550993" rpy="-1.5708 -0 0" />
      <geometry>
        <mesh filename="../meshes/visual/left_shoulder_yaw_visual.stl" />
      </geometry>
      <material name="left_shoulder_yaw_parts_material">
        <color rgba="0.933333 0.933333 0.933333 1" />
      </material>
    </visual>
  </link>
  <!-- Link left_elbow_pitch -->
  <link name="left_elbow_pitch">
    <inertial>
      <origin xyz="-0.00956573 0.0258355 -2.70123e-07" rpy="0 0 0" />
      <mass value="0.11" />
      <inertia ixx="0.000116342" ixy="7.43616e-06" ixz="-4.1438e-08" iyy="9.70555e-05" iyz="-5.662e-09" izz="7.93924e-05" />
    </inertial>
    <!-- Part left_elbow_pitch_parts -->
    <visual>
      <origin xyz="-0.00956573 0.0258355 -2.70123e-07" rpy="0 -0 -0" />
      <geometry>
        <mesh filename="../meshes/visual/left_elbow_pitch_visual.stl" />
      </geometry>
      <material name="left_elbow_pitch_parts_material">
        <color rgba="0.933333 0.933333 0.933333 1" />
      </material>
    </visual>
  </link>
  <!-- Link left_wrist_yaw -->
  <link name="left_wrist_yaw">
    <inertial>
      <origin xyz="-1.95914e-05 -1.82827e-05 -0.0591926" rpy="0 0 0" />
      <mass value="0.540556" />
      <inertia ixx="0.000852062" ixy="5.7427e-08" ixz="5.92015e-07" iyy="0.000858077" iyz="-2.89184e-07" izz="0.000282536" />
    </inertial>
    <!-- Part left_wrist_yaw_parts -->
    <collision>
      <origin xyz="-0 0 -0.025" rpy="0 0 0" />
      <geometry>
        <cylinder length="0.06" radius="0.03" />
      </geometry>
    </collision>
    <visual>
      <origin xyz="-1.95914e-05 -1.82827e-05 -0.0591926" rpy="-1.5708 -0 -0" />
      <geometry>
        <mesh filename="../meshes/visual/left_wrist_yaw_visual.stl" />
      </geometry>
      <material name="left_wrist_yaw_parts_material">
        <color rgba="0.932995 0.933039 0.933079 1" />
      </material>
    </visual>
  </link>
  <!-- Link left_wrist_roll -->
  <link name="left_wrist_roll">
    <inertial>
      <origin xyz="3.48e-10 1e-12 -2.12e-10" rpy="0 0 0" />
      <mass value="0.25" />
      <inertia ixx="7.92687e-05" ixy="0" ixz="0" iyy="9.19125e-05" iyz="-6.7e-11" izz="9.04076e-05" />
    </inertial>
    <!-- Part left_wrist_roll_parts -->
    <visual>
      <origin xyz="3.48e-10 1e-12 -2.12e-10" rpy="0 0 -0" />
      <geometry>
        <mesh filename="../meshes/visual/left_wrist_roll_visual.stl" />
      </geometry>
      <material name="left_wrist_roll_parts_material">
        <color rgba="0.933333 0.933333 0.933333 1" />
      </material>
    </visual>
  </link>
  <!-- Link left_hand -->
  <link name="left_hand">
    <inertial>
      <origin xyz="-0.00375869 0.0307393 -0.0039657" rpy="0 0 0" />
      <mass value="0.0692791" />
      <inertia ixx="5.76781e-05" ixy="4.16691e-06" ixz="-1.71469e-06" iyy="3.89472e-05" iyz="4.15711e-06" izz="3.02802e-05" />
    </inertial>
    <!-- Part left_hand_parts -->
    <collision>
      <origin xyz="0 0.07 -0" rpy="1.5708 -0 -1.5708" />
      <geometry>
        <box size="0.1 0.07 0.015" />
      </geometry>
    </collision>
    <visual>
      <origin xyz="-0.00375869 0.0307393 -0.0039657" rpy="-0 -1.5708 0" />
      <geometry>
        <mesh filename="../meshes/visual/left_hand_visual.stl" />
      </geometry>
      <material name="left_hand_parts_material">
        <color rgba="0.933333 0.933333 0.933333 1" />
      </material>
    </visual>
  </link>
  <!-- Link left_finger1_j1 -->
  <link name="left_finger1_j1">
    <inertial>
      <origin xyz="-0 0.0025 0" rpy="0 0 0" />
      <mass value="0.000744" />
      <inertia ixx="1.0478e-08" ixy="-0" ixz="-0" iyy="1.5128e-08" iyz="0" izz="7.75e-09" />
    </inertial>
    <!-- Part left_finger1_j1_parts -->
    <visual>
      <origin xyz="-0 0.0025 0" rpy="-1.5708 -0.785398 1.5708" />
      <geometry>
        <mesh filename="../meshes/visual/left_finger1_j1_visual.stl" />
      </geometry>
      <material name="left_finger1_j1_parts_material">
        <color rgba="0.933333 0.933333 0.933333 1" />
      </material>
    </visual>
  </link>
  <!-- Link left_finger1_j2 -->
  <link name="left_finger1_j2">
    <inertial>
      <origin xyz="0 0.01 0" rpy="0 0 0" />
      <mass value="0.002976" />
      <inertia ixx="1.24e-07" ixy="-0" ixz="-0" iyy="6.0512e-08" iyz="0" izz="1.34912e-07" />
    </inertial>
    <!-- Part left_finger1_j2_parts -->
    <visual>
      <origin xyz="0 0.01 0" rpy="0 -0 0.785398" />
      <geometry>
        <mesh filename="../meshes/visual/left_finger1_j2_visual.stl" />
      </geometry>
      <material name="left_finger1_j2_parts_material">
        <color rgba="0.933333 0.933333 0.933333 1" />
      </material>
    </visual>
  </link>
  <!-- Link left_finger1_j3 -->
  <link name="left_finger1_j3">
    <inertial>
      <origin xyz="-0 0.01 0" rpy="0 0 0" />
      <mass value="0.001984" />
      <inertia ixx="8.2667e-08" ixy="-0" ixz="0" iyy="2.7115e-08" iyz="-0" izz="7.6715e-08" />
    </inertial>
    <!-- Part left_finger1_j3_parts -->
    <visual>
      <origin xyz="-0 0.01 0" rpy="-1.5708 -0.785398 1.5708" />
      <geometry>
        <mesh filename="../meshes/visual/left_finger1_j3_visual.stl" />
      </geometry>
      <material name="left_finger1_j3_parts_material">
        <color rgba="0.933333 0.933333 0.933333 1" />
      </material>
    </visual>
  </link>
  <!-- Link left_finger1_j4 -->
  <link name="left_finger1_j4">
    <inertial>
      <origin xyz="-0.000271318 0.00682171 -0" rpy="0 0 0" />
      <mass value="0.001333" />
      <inertia ixx="3.2905e-08" ixy="2.247e-09" ixz="0" iyy="1.7887e-08" iyz="-0" izz="2.8576e-08" />
    </inertial>
    <!-- Part left_finger1_j4_parts -->
    <visual>
      <origin xyz="-0.000271318 0.00682171 -0" rpy="-1.5708 -0.785398 1.5708" />
      <geometry>
        <mesh filename="../meshes/visual/left_finger1_j4_visual.stl" />
      </geometry>
      <material name="left_finger1_j4_parts_material">
        <color rgba="0.933333 0.933333 0.933333 1" />
      </material>
    </visual>
  </link>
  <!-- Joint from left_finger1_j3 to left_finger1_j4 -->
  <joint name="left_finger1_j4" type="revolute">
    <origin xyz="0 0.025 -0" rpy="-0 0 0" />
    <parent link="left_finger1_j3" />
    <child link="left_finger1_j4" />
    <axis xyz="0 0 1" />
    <limit effort="10" velocity="100" lower="-1.5708" upper="0.0872665" />
    <joint_properties friction="0.1" />
  </joint>
  <!-- Joint from left_finger1_j2 to left_finger1_j3 -->
  <joint name="left_finger1_j3" type="revolute">
    <origin xyz="0 0.025 0" rpy="-0 1.5708 0" />
    <parent link="left_finger1_j2" />
    <child link="left_finger1_j3" />
    <axis xyz="0 0 1" />
    <limit effort="10" velocity="100" lower="-1.91986" upper="0.0872665" />
    <joint_properties friction="0.1" />
  </joint>
  <!-- Joint from left_finger1_j1 to left_finger1_j2 -->
  <joint name="left_finger1_j2" type="revolute">
    <origin xyz="0 0.01 0" rpy="-0 -1.5708 0" />
    <parent link="left_finger1_j1" />
    <child link="left_finger1_j2" />
    <axis xyz="0 0 1" />
    <limit effort="10" velocity="100" lower="-0.349066" upper="0.349066" />
    <joint_properties friction="0.1" />
  </joint>
  <!-- Joint from left_hand to left_finger1_j1 -->
  <joint name="left_finger1_j1" type="revolute">
    <origin xyz="0 0.035 0.03" rpy="0.785398 0 -0" />
    <parent link="left_hand" />
    <child link="left_finger1_j1" />
    <axis xyz="0 0 1" />
    <limit effort="10" velocity="100" lower="-1.5708" upper="-0" />
    <joint_properties friction="0.1" />
  </joint>
  <!-- Link left_finger2_j1 -->
  <link name="left_finger2_j1">
    <inertial>
      <origin xyz="-0 0.0025 0" rpy="0 0 0" />
      <mass value="0.000496" />
      <inertia ixx="3.679e-09" ixy="-0" ixz="0" iyy="6.779e-09" iyz="-0" izz="5.167e-09" />
    </inertial>
    <!-- Part left_finger2_j1_parts -->
    <visual>
      <origin xyz="-0 0.0025 0" rpy="0 -1.5708 0" />
      <geometry>
        <mesh filename="../meshes/visual/left_finger2_j1_visual.stl" />
      </geometry>
      <material name="left_finger2_j1_parts_material">
        <color rgba="0.933333 0.933333 0.933333 1" />
      </material>
    </visual>
  </link>
  <!-- Link left_finger2_j2 -->
  <link name="left_finger2_j2">
    <inertial>
      <origin xyz="-0 0.0125 0" rpy="0 0 0" />
      <mass value="0.00248" />
      <inertia ixx="1.49833e-07" ixy="0" ixz="0" iyy="3.3893e-08" iyz="-0" izz="1.42393e-07" />
    </inertial>
    <!-- Part left_finger2_j2_parts -->
    <visual>
      <origin xyz="-0 0.0125 0" rpy="-0 -0 -0" />
      <geometry>
        <mesh filename="../meshes/visual/left_finger2_j2_visual.stl" />
      </geometry>
      <material name="left_finger2_j2_parts_material">
        <color rgba="0.933333 0.933333 0.933333 1" />
      </material>
    </visual>
  </link>
  <!-- Link left_finger2_j3 -->
  <link name="left_finger2_j3">
    <inertial>
      <origin xyz="0 0.01 0" rpy="0 0 0" />
      <mass value="0.0011904" />
      <inertia ixx="4.3251e-08" ixy="0" ixz="-0" iyy="9.92e-09" iyz="-0" izz="4.6029e-08" />
    </inertial>
    <!-- Part left_finger2_j3_parts -->
    <visual>
      <origin xyz="0 0.01 0" rpy="0 -1.5708 0" />
      <geometry>
        <mesh filename="../meshes/visual/left_finger2_j3_visual.stl" />
      </geometry>
      <material name="left_finger2_j3_parts_material">
        <color rgba="0.933333 0.933333 0.933333 1" />
      </material>
    </visual>
  </link>
  <!-- Link left_finger2_j4 -->
  <link name="left_finger2_j4">
    <inertial>
      <origin xyz="-0.000432099 0.00438272 0" rpy="0 0 0" />
      <mass value="0.0004185" />
      <inertia ixx="3.877e-09" ixy="6.61e-10" ixz="-0" iyy="2.909e-09" iyz="0" izz="5.043e-09" />
    </inertial>
    <!-- Part left_finger2_j4_parts -->
    <visual>
      <origin xyz="-0.000432099 0.00438272 0" rpy="0 -1.5708 0" />
      <geometry>
        <mesh filename="../meshes/visual/left_finger2_j4_visual.stl" />
      </geometry>
      <material name="left_finger2_j4_parts_material">
        <color rgba="0.933333 0.933333 0.933333 1" />
      </material>
    </visual>
  </link>
  <!-- Joint from left_finger2_j3 to left_finger2_j4 -->
  <joint name="left_finger2_j4" type="revolute">
    <origin xyz="0 0.025 0" rpy="-0 -0 -0" />
    <parent link="left_finger2_j3" />
    <child link="left_finger2_j4" />
    <axis xyz="0 0 1" />
    <limit effort="10" velocity="100" lower="-1.5708" upper="0.0872665" />
    <joint_properties friction="0.1" />
  </joint>
  <!-- Joint from left_finger2_j2 to left_finger2_j3 -->
  <joint name="left_finger2_j3" type="revolute">
    <origin xyz="0 0.03 -0" rpy="-0 1.5708 0" />
    <parent link="left_finger2_j2" />
    <child link="left_finger2_j3" />
    <axis xyz="0 0 1" />
    <limit effort="10" velocity="100" lower="-1.91986" upper="0.0872665" />
    <joint_properties friction="0.1" />
  </joint>
  <!-- Joint from left_finger2_j1 to left_finger2_j2 -->
  <joint name="left_finger2_j2" type="revolute">
    <origin xyz="0 0.01 0" rpy="-0 -1.5708 0" />
    <parent link="left_finger2_j1" />
    <child link="left_finger2_j2" />
    <axis xyz="0 0 1" />
    <limit effort="10" velocity="100" lower="-0.349066" upper="0.349066" />
    <joint_properties friction="0.1" />
  </joint>
  <!-- Joint from left_hand to left_finger2_j1 -->
  <joint name="left_finger2_j1" type="revolute">
    <origin xyz="0 0.07 0.015" rpy="-0 0 -0" />
    <parent link="left_hand" />
    <child link="left_finger2_j1" />
    <axis xyz="0 0 1" />
    <limit effort="10" velocity="100" lower="-1.91986" upper="0.0872665" />
    <joint_properties friction="0.1" />
  </joint>
  <!-- Link left_finger3_j1 -->
  <link name="left_finger3_j1">
    <inertial>
      <origin xyz="0 0.0025 0" rpy="0 0 0" />
      <mass value="0.000496" />
      <inertia ixx="3.679e-09" ixy="-0" ixz="0" iyy="6.779e-09" iyz="0" izz="5.167e-09" />
    </inertial>
    <!-- Part left_finger3_j1_parts -->
    <visual>
      <origin xyz="0 0.0025 0" rpy="0 -1.5708 0" />
      <geometry>
        <mesh filename="../meshes/visual/left_finger3_j1_visual.stl" />
      </geometry>
      <material name="left_finger3_j1_parts_material">
        <color rgba="0.933333 0.933333 0.933333 1" />
      </material>
    </visual>
  </link>
  <!-- Link left_finger3_j2 -->
  <link name="left_finger3_j2">
    <inertial>
      <origin xyz="-0 0.015 -0" rpy="0 0 0" />
      <mass value="0.002976" />
      <inertia ixx="2.48e-07" ixy="-0" ixz="0" iyy="4.0672e-08" iyz="0" izz="2.39072e-07" />
    </inertial>
    <!-- Part left_finger3_j2_parts -->
    <visual>
      <origin xyz="-0 0.015 -0" rpy="-0 0 -0" />
      <geometry>
        <mesh filename="../meshes/visual/left_finger3_j2_visual.stl" />
      </geometry>
      <material name="left_finger3_j2_parts_material">
        <color rgba="0.933333 0.933333 0.933333 1" />
      </material>
    </visual>
  </link>
  <!-- Link left_finger3_j3 -->
  <link name="left_finger3_j3">
    <inertial>
      <origin xyz="-0 0.0125 0" rpy="0 0 0" />
      <mass value="0.001488" />
      <inertia ixx="8.1964e-08" ixy="-0" ixz="0" iyy="1.24e-08" iyz="0" izz="8.5436e-08" />
    </inertial>
    <!-- Part left_finger3_j3_parts -->
    <visual>
      <origin xyz="-0 0.0125 0" rpy="0 -1.5708 0" />
      <geometry>
        <mesh filename="../meshes/visual/left_finger3_j3_visual.stl" />
      </geometry>
      <material name="left_finger3_j3_parts_material">
        <color rgba="0.933333 0.933333 0.933333 1" />
      </material>
    </visual>
  </link>
  <!-- Link left_finger3_j4 -->
  <link name="left_finger3_j4">
    <inertial>
      <origin xyz="-0.000432099 0.00438272 0" rpy="0 0 0" />
      <mass value="0.0004185" />
      <inertia ixx="3.877e-09" ixy="6.61e-10" ixz="-0" iyy="2.909e-09" iyz="-0" izz="5.043e-09" />
    </inertial>
    <!-- Part left_finger3_j4_parts -->
    <visual>
      <origin xyz="-0.000432099 0.00438272 0" rpy="0 -1.5708 0" />
      <geometry>
        <mesh filename="../meshes/visual/left_finger3_j4_visual.stl" />
      </geometry>
      <material name="left_finger3_j4_parts_material">
        <color rgba="0.933333 0.933333 0.933333 1" />
      </material>
    </visual>
  </link>
  <!-- Joint from left_finger3_j3 to left_finger3_j4 -->
  <joint name="left_finger3_j4" type="revolute">
    <origin xyz="-0 0.03 0" rpy="0 -0 0" />
    <parent link="left_finger3_j3" />
    <child link="left_finger3_j4" />
    <axis xyz="0 0 1" />
    <limit effort="10" velocity="100" lower="-1.5708" upper="0.0872665" />
    <joint_properties friction="0.1" />
  </joint>
  <!-- Joint from left_finger3_j2 to left_finger3_j3 -->
  <joint name="left_finger3_j3" type="revolute">
    <origin xyz="0 0.035 0" rpy="0 1.5708 0" />
    <parent link="left_finger3_j2" />
    <child link="left_finger3_j3" />
    <axis xyz="0 0 1" />
    <limit effort="10" velocity="100" lower="-1.91986" upper="0.0872665" />
    <joint_properties friction="0.1" />
  </joint>
  <!-- Joint from left_finger3_j1 to left_finger3_j2 -->
  <joint name="left_finger3_j2" type="revolute">
    <origin xyz="-0 0.01 -0" rpy="0 -1.5708 0" />
    <parent link="left_finger3_j1" />
    <child link="left_finger3_j2" />
    <axis xyz="0 0 1" />
    <limit effort="10" velocity="100" lower="-0.349066" upper="0.349066" />
    <joint_properties friction="0.1" />
  </joint>
  <!-- Joint from left_hand to left_finger3_j1 -->
  <joint name="left_finger3_j1" type="revolute">
    <origin xyz="0 0.075 0" rpy="-0 0 -0" />
    <parent link="left_hand" />
    <child link="left_finger3_j1" />
    <axis xyz="0 0 1" />
    <limit effort="10" velocity="100" lower="-1.91986" upper="0.0872665" />
    <joint_properties friction="0.1" />
  </joint>
  <!-- Link left_finger4_j1 -->
  <link name="left_finger4_j1">
    <inertial>
      <origin xyz="-0 0.0025 0" rpy="0 0 0" />
      <mass value="0.000496" />
      <inertia ixx="3.679e-09" ixy="-0" ixz="0" iyy="6.779e-09" iyz="0" izz="5.167e-09" />
    </inertial>
    <!-- Part left_finger4_j1_parts -->
    <visual>
      <origin xyz="-0 0.0025 0" rpy="0 -1.5708 0" />
      <geometry>
        <mesh filename="../meshes/visual/left_finger4_j1_visual.stl" />
      </geometry>
      <material name="left_finger4_j1_parts_material">
        <color rgba="0.933333 0.933333 0.933333 1" />
      </material>
    </visual>
  </link>
  <!-- Link left_finger4_j2 -->
  <link name="left_finger4_j2">
    <inertial>
      <origin xyz="0 0.015 -0" rpy="0 0 0" />
      <mass value="0.002976" />
      <inertia ixx="2.48e-07" ixy="-0" ixz="0" iyy="4.0672e-08" iyz="-0" izz="2.39072e-07" />
    </inertial>
    <!-- Part left_finger4_j2_parts -->
    <visual>
      <origin xyz="0 0.015 -0" rpy="0 -0 -0" />
      <geometry>
        <mesh filename="../meshes/visual/left_finger4_j2_visual.stl" />
      </geometry>
      <material name="left_finger4_j2_parts_material">
        <color rgba="0.933333 0.933333 0.933333 1" />
      </material>
    </visual>
  </link>
  <!-- Link left_finger4_j3 -->
  <link name="left_finger4_j3">
    <inertial>
      <origin xyz="0 0.01 0" rpy="0 0 0" />
      <mass value="0.0011904" />
      <inertia ixx="4.3251e-08" ixy="-0" ixz="-0" iyy="9.92e-09" iyz="-0" izz="4.6029e-08" />
    </inertial>
    <!-- Part left_finger4_j3_parts -->
    <visual>
      <origin xyz="0 0.01 0" rpy="0 -1.5708 0" />
      <geometry>
        <mesh filename="../meshes/visual/left_finger4_j3_visual.stl" />
      </geometry>
      <material name="left_finger4_j3_parts_material">
        <color rgba="0.933333 0.933333 0.933333 1" />
      </material>
    </visual>
  </link>
  <!-- Link left_finger4_j4 -->
  <link name="left_finger4_j4">
    <inertial>
      <origin xyz="-0.000432099 0.00438272 0" rpy="0 0 0" />
      <mass value="0.0004185" />
      <inertia ixx="3.877e-09" ixy="6.61e-10" ixz="0" iyy="2.909e-09" iyz="0" izz="5.043e-09" />
    </inertial>
    <!-- Part left_finger4_j4_parts -->
    <visual>
      <origin xyz="-0.000432099 0.00438272 0" rpy="0 -1.5708 0" />
      <geometry>
        <mesh filename="../meshes/visual/left_finger4_j4_visual.stl" />
      </geometry>
      <material name="left_finger4_j4_parts_material">
        <color rgba="0.933333 0.933333 0.933333 1" />
      </material>
    </visual>
  </link>
  <!-- Joint from left_finger4_j3 to left_finger4_j4 -->
  <joint name="left_finger4_j4" type="revolute">
    <origin xyz="0 0.025 -0" rpy="-0 -0 -0" />
    <parent link="left_finger4_j3" />
    <child link="left_finger4_j4" />
    <axis xyz="0 0 1" />
    <limit effort="10" velocity="100" lower="-1.5708" upper="0.0872665" />
    <joint_properties friction="0.1" />
  </joint>
  <!-- Joint from left_finger4_j2 to left_finger4_j3 -->
  <joint name="left_finger4_j3" type="revolute">
    <origin xyz="0 0.035 0" rpy="0 1.5708 0" />
    <parent link="left_finger4_j2" />
    <child link="left_finger4_j3" />
    <axis xyz="0 0 1" />
    <limit effort="10" velocity="100" lower="-1.91986" upper="0.0872665" />
    <joint_properties friction="0.1" />
  </joint>
  <!-- Joint from left_finger4_j1 to left_finger4_j2 -->
  <joint name="left_finger4_j2" type="revolute">
    <origin xyz="0 0.01 0" rpy="-0 -1.5708 0" />
    <parent link="left_finger4_j1" />
    <child link="left_finger4_j2" />
    <axis xyz="0 0 1" />
    <limit effort="10" velocity="100" lower="-0.349066" upper="0.349066" />
    <joint_properties friction="0.1" />
  </joint>
  <!-- Joint from left_hand to left_finger4_j1 -->
  <joint name="left_finger4_j1" type="revolute">
    <origin xyz="0 0.07 -0.015" rpy="-0 0 -0" />
    <parent link="left_hand" />
    <child link="left_finger4_j1" />
    <axis xyz="0 0 1" />
    <limit effort="10" velocity="100" lower="-1.91986" upper="0.0872665" />
    <joint_properties friction="0.1" />
  </joint>
  <!-- Link left_finger5_j1 -->
  <link name="left_finger5_j1">
    <inertial>
      <origin xyz="0 0.0025 -0" rpy="0 0 0" />
      <mass value="0.000496" />
      <inertia ixx="3.679e-09" ixy="0" ixz="0" iyy="6.779e-09" iyz="-0" izz="5.167e-09" />
    </inertial>
    <!-- Part left_finger5_j1_parts -->
    <visual>
      <origin xyz="0 0.0025 -0" rpy="0 -1.5708 0" />
      <geometry>
        <mesh filename="../meshes/visual/left_finger5_j1_visual.stl" />
      </geometry>
      <material name="left_finger5_j1_parts_material">
        <color rgba="0.933333 0.933333 0.933333 1" />
      </material>
    </visual>
  </link>
  <!-- Link left_finger5_j2 -->
  <link name="left_finger5_j2">
    <inertial>
      <origin xyz="0 0.01 0" rpy="0 0 0" />
      <mass value="0.001984" />
      <inertia ixx="8.2667e-08" ixy="-0" ixz="-0" iyy="2.7115e-08" iyz="0" izz="7.6715e-08" />
    </inertial>
    <!-- Part left_finger5_j2_parts -->
    <visual>
      <origin xyz="0 0.01 0" rpy="0 -0 -0" />
      <geometry>
        <mesh filename="../meshes/visual/left_finger5_j2_visual.stl" />
      </geometry>
      <material name="left_finger5_j2_parts_material">
        <color rgba="0.933333 0.933333 0.933333 1" />
      </material>
    </visual>
  </link>
  <!-- Link left_finger5_j3 -->
  <link name="left_finger5_j3">
    <inertial>
      <origin xyz="-0 0.0075 -0" rpy="0 0 0" />
      <mass value="0.0008928" />
      <inertia ixx="1.9418e-08" ixy="-0" ixz="0" iyy="7.44e-09" iyz="0" izz="2.1502e-08" />
    </inertial>
    <!-- Part left_finger5_j3_parts -->
    <visual>
      <origin xyz="-0 0.0075 -0" rpy="0 -1.5708 0" />
      <geometry>
        <mesh filename="../meshes/visual/left_finger5_j3_visual.stl" />
      </geometry>
      <material name="left_finger5_j3_parts_material">
        <color rgba="0.933333 0.933333 0.933333 1" />
      </material>
    </visual>
  </link>
  <!-- Link left_finger5_j4 -->
  <link name="left_finger5_j4">
    <inertial>
      <origin xyz="-0.000432099 0.00438272 -0" rpy="0 0 0" />
      <mass value="0.0004185" />
      <inertia ixx="3.877e-09" ixy="6.61e-10" ixz="-0" iyy="2.909e-09" iyz="0" izz="5.043e-09" />
    </inertial>
    <!-- Part left_finger5_j4_parts -->
    <visual>
      <origin xyz="-0.000432099 0.00438272 -0" rpy="0 -1.5708 0" />
      <geometry>
        <mesh filename="../meshes/visual/left_finger5_j4_visual.stl" />
      </geometry>
      <material name="left_finger5_j4_parts_material">
        <color rgba="0.933333 0.933333 0.933333 1" />
      </material>
    </visual>
  </link>
  <!-- Joint from left_finger5_j3 to left_finger5_j4 -->
  <joint name="left_finger5_j4" type="revolute">
    <origin xyz="0 0.02 0" rpy="0 -0 0" />
    <parent link="left_finger5_j3" />
    <child link="left_finger5_j4" />
    <axis xyz="0 0 1" />
    <limit effort="10" velocity="100" lower="-1.5708" upper="0.0872665" />
    <joint_properties friction="0.1" />
  </joint>
  <!-- Joint from left_finger5_j2 to left_finger5_j3 -->
  <joint name="left_finger5_j3" type="revolute">
    <origin xyz="0 0.025 0" rpy="0 1.5708 0" />
    <parent link="left_finger5_j2" />
    <child link="left_finger5_j3" />
    <axis xyz="0 0 1" />
    <limit effort="10" velocity="100" lower="-1.91986" upper="0.0872665" />
    <joint_properties friction="0.1" />
  </joint>
  <!-- Joint from left_finger5_j1 to left_finger5_j2 -->
  <joint name="left_finger5_j2" type="revolute">
    <origin xyz="-0 0.01 0" rpy="-0 -1.5708 0" />
    <parent link="left_finger5_j1" />
    <child link="left_finger5_j2" />
    <axis xyz="0 0 1" />
    <limit effort="10" velocity="100" lower="-0.349066" upper="0.349066" />
    <joint_properties friction="0.1" />
  </joint>
  <!-- Joint from left_hand to left_finger5_j1 -->
  <joint name="left_finger5_j1" type="revolute">
    <origin xyz="0 0.065 -0.03" rpy="-0 0 -0" />
    <parent link="left_hand" />
    <child link="left_finger5_j1" />
    <axis xyz="0 0 1" />
    <limit effort="10" velocity="100" lower="-1.91986" upper="0.0872665" />
    <joint_properties friction="0.1" />
  </joint>
  <!-- Joint from left_wrist_roll to left_hand -->
  <joint name="left_wrist_pitch" type="revolute">
    <origin xyz="0 0 0" rpy="0 1.5708 0" />
    <parent link="left_wrist_roll" />
    <child link="left_hand" />
    <axis xyz="0 0 1" />
    <limit effort="5.5" velocity="100" lower="-0.785398" upper="0.785398" />
    <joint_properties friction="0.1" />
  </joint>
  <!-- Joint from left_wrist_yaw to left_wrist_roll -->
  <joint name="left_wrist_roll" type="revolute">
    <origin xyz="0 -0 -0.135" rpy="-1.5708 0 0" />
    <parent link="left_wrist_yaw" />
    <child link="left_wrist_roll" />
    <axis xyz="0 0 1" />
    <limit effort="5.5" velocity="100" lower="-0.698132" upper="0.698132" />
    <joint_properties friction="0.1" />
  </joint>
  <!-- Joint from left_elbow_pitch to left_wrist_yaw -->
  <joint name="left_wrist_yaw" type="revolute">
    <origin xyz="-0.01 0.055 0" rpy="1.5708 -0 -0" />
    <parent link="left_elbow_pitch" />
    <child link="left_wrist_yaw" />
    <axis xyz="0 0 1" />
    <limit effort="5.5" velocity="100" lower="-2.0944" upper="1.5708" />
    <joint_properties friction="0.1" />
  </joint>
  <!-- Joint from left_shoulder_yaw to left_elbow_pitch -->
  <joint name="left_elbow_pitch" type="revolute">
    <origin xyz="0.01 -0 -0.08" rpy="-1.5708 0 0" />
    <parent link="left_shoulder_yaw" />
    <child link="left_elbow_pitch" />
    <axis xyz="0 0 1" />
    <limit effort="14.0" velocity="100" lower="-2.35619" upper="0" />
    <joint_properties friction="0.1" />
  </joint>
  <!-- Joint from left_shoulder_roll to left_shoulder_yaw -->
  <joint name="left_shoulder_yaw" type="revolute">
    <origin xyz="0 0.12 0" rpy="1.5708 -1.5708 0" />
    <parent link="left_shoulder_roll" />
    <child link="left_shoulder_yaw" />
    <axis xyz="0 0 1" />
    <limit effort="14.0" velocity="100" lower="-1.5708" upper="1.5708" />
    <joint_properties friction="0.1" />
  </joint>
  <!-- Joint from left_shoulder_pitch to left_shoulder_roll -->
  <joint name="left_shoulder_roll" type="revolute">
    <origin xyz="0 0 0" rpy="1.5708 0.174533 1.5708" />
    <parent link="left_shoulder_pitch" />
    <child link="left_shoulder_roll" />
    <axis xyz="0 0 1" />
    <limit effort="14.0" velocity="100" lower="-1.5708" upper="1.91986" />
    <joint_properties friction="0.1" />
  </joint>
  <!-- Joint from chest to left_shoulder_pitch -->
  <joint name="left_shoulder_pitch" type="revolute">
    <origin xyz="-0.03 0.09 0.26" rpy="-1.39626 0 0" />
    <parent link="chest" />
    <child link="left_shoulder_pitch" />
    <axis xyz="0 0 1" />
    <limit effort="17.0" velocity="100" lower="-3.14159" upper="0.785398" />
    <joint_properties friction="0.1" />
  </joint>
  <!-- Link right_shoulder_pitch -->
  <link name="right_shoulder_pitch">
    <inertial>
      <origin xyz="6.27e-10 -0.00168619 0.00682299" rpy="0 0 0" />
      <mass value="0.375" />
      <inertia ixx="0.000232695" ixy="-7e-12" ixz="2e-12" iyy="0.000233203" iyz="1.40823e-05" izz="0.000199827" />
    </inertial>
    <!-- Part right_shoulder_pitch_parts -->
    <visual>
      <origin xyz="6.27e-10 -0.00168619 0.00682299" rpy="1.74533 0 0" />
      <geometry>
        <mesh filename="../meshes/visual/right_shoulder_pitch_visual.stl" />
      </geometry>
      <material name="right_shoulder_pitch_parts_material">
        <color rgba="0.933333 0.933333 0.933333 1" />
      </material>
    </visual>
  </link>
  <!-- Link right_shoulder_roll -->
  <link name="right_shoulder_roll">
    <inertial>
      <origin xyz="-1.01172e-07 0.0788914 2.6114e-08" rpy="0 0 0" />
      <mass value="0.42" />
      <inertia ixx="0.000535466" ixy="2.667e-09" ixz="-3.953e-09" iyy="0.000208176" iyz="-1.3e-11" izz="0.00050471" />
    </inertial>
    <!-- Part right_shoulder_roll_parts -->
    <visual>
      <origin xyz="-1.01172e-07 0.0788914 2.6114e-08" rpy="-3.14159 -1.5708 0" />
      <geometry>
        <mesh filename="../meshes/visual/right_shoulder_roll_visual.stl" />
      </geometry>
      <material name="right_shoulder_roll_parts_material">
        <color rgba="0.392063 0.392063 0.392063 1" />
      </material>
    </visual>
  </link>
  <!-- Link right_shoulder_yaw -->
  <link name="right_shoulder_yaw">
    <inertial>
      <origin xyz="0.00503646 -5.8721e-08 -0.0550993" rpy="0 0 0" />
      <mass value="0.43" />
      <inertia ixx="0.000494516" ixy="1.11e-10" ixz="4.80353e-05" iyy="0.000498658" iyz="1.121e-09" izz="0.000218183" />
    </inertial>
    <!-- Part right_shoulder_yaw_parts -->
    <collision>
      <origin xyz="0 0 0.03" rpy="0 -0 -1.5708" />
      <geometry>
        <cylinder length="0.08" radius="0.03" />
      </geometry>
    </collision>
    <visual>
      <origin xyz="0.00503646 -5.8721e-08 -0.0550993" rpy="1.5708 0 0" />
      <geometry>
        <mesh filename="../meshes/visual/right_shoulder_yaw_visual.stl" />
      </geometry>
      <material name="right_shoulder_yaw_parts_material">
        <color rgba="0.933333 0.933333 0.933333 1" />
      </material>
    </visual>
  </link>
  <!-- Link right_elbow_pitch -->
  <link name="right_elbow_pitch">
    <inertial>
      <origin xyz="-0.0095654 0.0258358 1.46047e-06" rpy="0 0 0" />
      <mass value="0.11" />
      <inertia ixx="0.000116343" ixy="7.43678e-06" ixz="3.8036e-08" iyy="9.70569e-05" iyz="6.815e-09" izz="7.93932e-05" />
    </inertial>
    <!-- Part right_elbow_pitch_parts -->
    <visual>
      <origin xyz="-0.0095654 0.0258358 1.46047e-06" rpy="-3.14159 -0 0" />
      <geometry>
        <mesh filename="../meshes/visual/right_elbow_pitch_visual.stl" />
      </geometry>
      <material name="right_elbow_pitch_parts_material">
        <color rgba="0.933333 0.933333 0.933333 1" />
      </material>
    </visual>
  </link>
  <!-- Link right_wrist_yaw -->
  <link name="right_wrist_yaw">
    <inertial>
      <origin xyz="1.99324e-07 2.65767e-05 -0.0592501" rpy="0 0 0" />
      <mass value="0.54" />
      <inertia ixx="0.000850282" ixy="2.867e-08" ixz="-3.809e-09" iyy="0.000856128" iyz="4.2812e-08" izz="0.000282295" />
    </inertial>
    <!-- Part right_wrist_yaw_parts -->
    <collision>
      <origin xyz="-0 -0 -0.025" rpy="-0 0 3.14159" />
      <geometry>
        <cylinder length="0.06" radius="0.03" />
      </geometry>
    </collision>
    <visual>
      <origin xyz="1.99324e-07 2.65767e-05 -0.0592501" rpy="1.5708 0 0" />
      <geometry>
        <mesh filename="../meshes/visual/right_wrist_yaw_visual.stl" />
      </geometry>
      <material name="right_wrist_yaw_parts_material">
        <color rgba="0.933333 0.933333 0.933333 1" />
      </material>
    </visual>
  </link>
  <!-- Link right_wrist_roll -->
  <link name="right_wrist_roll">
    <inertial>
      <origin xyz="4.084e-09 -2e-12 -2.02e-10" rpy="0 0 0" />
      <mass value="0.25" />
      <inertia ixx="7.92688e-05" ixy="-0" ixz="0" iyy="9.19094e-05" iyz="2.493e-09" izz="9.04084e-05" />
    </inertial>
    <!-- Part right_wrist_roll_parts -->
    <visual>
      <origin xyz="4.084e-09 -2e-12 -2.02e-10" rpy="-3.14159 -0 0" />
      <geometry>
        <mesh filename="../meshes/visual/right_wrist_roll_visual.stl" />
      </geometry>
      <material name="right_wrist_roll_parts_material">
        <color rgba="0.933333 0.933333 0.933333 1" />
      </material>
    </visual>
  </link>
  <!-- Link right_hand -->
  <link name="right_hand">
    <inertial>
      <origin xyz="0.00375875 0.0307394 -0.00396572" rpy="0 0 0" />
      <mass value="0.0692787" />
      <inertia ixx="5.76778e-05" ixy="-4.16677e-06" ixz="1.71477e-06" iyy="3.89469e-05" iyz="4.15709e-06" izz="3.028e-05" />
    </inertial>
    <!-- Part right_hand_parts -->
    <collision>
      <origin xyz="-0 0.07 -0" rpy="1.5708 0 1.5708" />
      <geometry>
        <box size="0.1 0.07 0.015" />
      </geometry>
    </collision>
    <visual>
      <origin xyz="0.00375875 0.0307394 -0.00396572" rpy="3.14159 -1.5708 0" />
      <geometry>
        <mesh filename="../meshes/visual/right_hand_visual.stl" />
      </geometry>
      <material name="right_hand_parts_material">
        <color rgba="0.933333 0.933333 0.933333 1" />
      </material>
    </visual>
  </link>
  <!-- Link right_finger1_j1 -->
  <link name="right_finger1_j1">
    <inertial>
      <origin xyz="0 0.0025 0" rpy="0 0 0" />
      <mass value="0.000744" />
      <inertia ixx="1.0478e-08" ixy="0" ixz="0" iyy="1.5128e-08" iyz="-0" izz="7.75e-09" />
    </inertial>
    <!-- Part right_finger1_j1_parts -->
    <visual>
      <origin xyz="0 0.0025 0" rpy="1.5708 -0.785398 1.5708" />
      <geometry>
        <mesh filename="../meshes/visual/right_finger1_j1_visual.stl" />
      </geometry>
      <material name="right_finger1_j1_parts_material">
        <color rgba="0.933333 0.933333 0.933333 1" />
      </material>
    </visual>
  </link>
  <!-- Link right_finger1_j2 -->
  <link name="right_finger1_j2">
    <inertial>
      <origin xyz="-0 0.01 -0" rpy="0 0 0" />
      <mass value="0.002976" />
      <inertia ixx="1.24e-07" ixy="0" ixz="0" iyy="6.0512e-08" iyz="-0" izz="1.34912e-07" />
    </inertial>
    <!-- Part right_finger1_j2_parts -->
    <visual>
      <origin xyz="-0 0.01 -0" rpy="-0 0 2.35619" />
      <geometry>
        <mesh filename="../meshes/visual/right_finger1_j2_visual.stl" />
      </geometry>
      <material name="right_finger1_j2_parts_material">
        <color rgba="0.933333 0.933333 0.933333 1" />
      </material>
    </visual>
  </link>
  <!-- Link right_finger1_j3 -->
  <link name="right_finger1_j3">
    <inertial>
      <origin xyz="-0 0.01 0" rpy="0 0 0" />
      <mass value="0.001984" />
      <inertia ixx="8.2667e-08" ixy="0" ixz="0" iyy="2.7115e-08" iyz="-0" izz="7.6715e-08" />
    </inertial>
    <!-- Part right_finger1_j3_parts -->
    <visual>
      <origin xyz="-0 0.01 0" rpy="1.5708 -0.785398 1.5708" />
      <geometry>
        <mesh filename="../meshes/visual/right_finger1_j3_visual.stl" />
      </geometry>
      <material name="right_finger1_j3_parts_material">
        <color rgba="0.933333 0.933333 0.933333 1" />
      </material>
    </visual>
  </link>
  <!-- Link right_finger1_j4 -->
  <link name="right_finger1_j4">
    <inertial>
      <origin xyz="0.000271318 0.00682171 -0" rpy="0 0 0" />
      <mass value="0.001333" />
      <inertia ixx="3.2905e-08" ixy="-2.247e-09" ixz="0" iyy="1.7887e-08" iyz="0" izz="2.8576e-08" />
    </inertial>
    <!-- Part right_finger1_j4_parts -->
    <visual>
      <origin xyz="0.000271318 0.00682171 -0" rpy="1.5708 -0.785398 1.5708" />
      <geometry>
        <mesh filename="../meshes/visual/right_finger1_j4_visual.stl" />
      </geometry>
      <material name="right_finger1_j4_parts_material">
        <color rgba="0.933333 0.933333 0.933333 1" />
      </material>
    </visual>
  </link>
  <!-- Joint from right_finger1_j3 to right_finger1_j4 -->
  <joint name="right_finger1_j4" type="revolute">
    <origin xyz="0 0.025 -0" rpy="-0 -0 0" />
    <parent link="right_finger1_j3" />
    <child link="right_finger1_j4" />
    <axis xyz="0 0 1" />
    <limit effort="10" velocity="100" lower="-0.0872665" upper="1.5708" />
    <joint_properties friction="0.1" />
  </joint>
  <!-- Joint from right_finger1_j2 to right_finger1_j3 -->
  <joint name="right_finger1_j3" type="revolute">
    <origin xyz="-0 0.025 -0" rpy="-0 -1.5708 0" />
    <parent link="right_finger1_j2" />
    <child link="right_finger1_j3" />
    <axis xyz="0 0 1" />
    <limit effort="10" velocity="100" lower="-0.0872665" upper="1.91986" />
    <joint_properties friction="0.1" />
  </joint>
  <!-- Joint from right_finger1_j1 to right_finger1_j2 -->
  <joint name="right_finger1_j2" type="revolute">
    <origin xyz="0 0.01 0" rpy="-0 1.5708 0" />
    <parent link="right_finger1_j1" />
    <child link="right_finger1_j2" />
    <axis xyz="0 0 1" />
    <limit effort="10" velocity="100" lower="-0.349066" upper="0.349066" />
    <joint_properties friction="0.1" />
  </joint>
  <!-- Joint from right_hand to right_finger1_j1 -->
  <joint name="right_finger1_j1" type="revolute">
    <origin xyz="0 0.035 0.03" rpy="0.785398 0 -0" />
    <parent link="right_hand" />
    <child link="right_finger1_j1" />
    <axis xyz="0 0 1" />
    <limit effort="10" velocity="100" lower="0" upper="1.5708" />
    <joint_properties friction="0.1" />
  </joint>
  <!-- Link right_finger2_j1 -->
  <link name="right_finger2_j1">
    <inertial>
      <origin xyz="0 0.0025 -0" rpy="0 0 0" />
      <mass value="0.000496" />
      <inertia ixx="3.679e-09" ixy="0" ixz="-0" iyy="6.779e-09" iyz="-0" izz="5.167e-09" />
    </inertial>
    <!-- Part right_finger2_j1_parts -->
    <visual>
      <origin xyz="0 0.0025 -0" rpy="3.14159 -1.5708 0" />
      <geometry>
        <mesh filename="../meshes/visual/right_finger2_j1_visual.stl" />
      </geometry>
      <material name="right_finger2_j1_parts_material">
        <color rgba="0.933333 0.933333 0.933333 1" />
      </material>
    </visual>
  </link>
  <!-- Link right_finger2_j2 -->
  <link name="right_finger2_j2">
    <inertial>
      <origin xyz="0 0.0125 0" rpy="0 0 0" />
      <mass value="0.00248" />
      <inertia ixx="1.49833e-07" ixy="-0" ixz="-0" iyy="3.3893e-08" iyz="-0" izz="1.42393e-07" />
    </inertial>
    <!-- Part right_finger2_j2_parts -->
    <visual>
      <origin xyz="0 0.0125 0" rpy="-0 0 -3.14159" />
      <geometry>
        <mesh filename="../meshes/visual/right_finger2_j2_visual.stl" />
      </geometry>
      <material name="right_finger2_j2_parts_material">
        <color rgba="0.933333 0.933333 0.933333 1" />
      </material>
    </visual>
  </link>
  <!-- Link right_finger2_j3 -->
  <link name="right_finger2_j3">
    <inertial>
      <origin xyz="0 0.01 0" rpy="0 0 0" />
      <mass value="0.0011904" />
      <inertia ixx="4.3251e-08" ixy="-0" ixz="0" iyy="9.92e-09" iyz="0" izz="4.6029e-08" />
    </inertial>
    <!-- Part right_finger2_j3_parts -->
    <visual>
      <origin xyz="0 0.01 0" rpy="-3.14159 -1.5708 0" />
      <geometry>
        <mesh filename="../meshes/visual/right_finger2_j3_visual.stl" />
      </geometry>
      <material name="right_finger2_j3_parts_material">
        <color rgba="0.933333 0.933333 0.933333 1" />
      </material>
    </visual>
  </link>
  <!-- Link right_finger2_j4 -->
  <link name="right_finger2_j4">
    <inertial>
      <origin xyz="0.000432099 0.00438272 0" rpy="0 0 0" />
      <mass value="0.0004185" />
      <inertia ixx="3.877e-09" ixy="-6.61e-10" ixz="-0" iyy="2.909e-09" iyz="-0" izz="5.043e-09" />
    </inertial>
    <!-- Part right_finger2_j4_parts -->
    <visual>
      <origin xyz="0.000432099 0.00438272 0" rpy="-3.14159 -1.5708 0" />
      <geometry>
        <mesh filename="../meshes/visual/right_finger2_j4_visual.stl" />
      </geometry>
      <material name="right_finger2_j4_parts_material">
        <color rgba="0.933333 0.933333 0.933333 1" />
      </material>
    </visual>
  </link>
  <!-- Joint from right_finger2_j3 to right_finger2_j4 -->
  <joint name="right_finger2_j4" type="revolute">
    <origin xyz="0 0.025 0" rpy="0 0 -0" />
    <parent link="right_finger2_j3" />
    <child link="right_finger2_j4" />
    <axis xyz="0 0 1" />
    <limit effort="10" velocity="100" lower="-0.0872665" upper="1.5708" />
    <joint_properties friction="0.1" />
  </joint>
  <!-- Joint from right_finger2_j2 to right_finger2_j3 -->
  <joint name="right_finger2_j3" type="revolute">
    <origin xyz="0 0.03 0" rpy="-0 -1.5708 0" />
    <parent link="right_finger2_j2" />
    <child link="right_finger2_j3" />
    <axis xyz="0 0 1" />
    <limit effort="10" velocity="100" lower="-0.0872665" upper="1.91986" />
    <joint_properties friction="0.1" />
  </joint>
  <!-- Joint from right_finger2_j1 to right_finger2_j2 -->
  <joint name="right_finger2_j2" type="revolute">
    <origin xyz="0 0.01 0" rpy="0 1.5708 0" />
    <parent link="right_finger2_j1" />
    <child link="right_finger2_j2" />
    <axis xyz="0 0 1" />
    <limit effort="10" velocity="100" lower="-0.349066" upper="0.349066" />
    <joint_properties friction="0.1" />
  </joint>
  <!-- Joint from right_hand to right_finger2_j1 -->
  <joint name="right_finger2_j1" type="revolute">
    <origin xyz="0 0.07 0.015" rpy="0 0 -0" />
    <parent link="right_hand" />
    <child link="right_finger2_j1" />
    <axis xyz="0 0 1" />
    <limit effort="10" velocity="100" lower="-0.0872665" upper="1.91986" />
    <joint_properties friction="0.1" />
  </joint>
  <!-- Link right_finger3_j1 -->
  <link name="right_finger3_j1">
    <inertial>
      <origin xyz="0 0.0025 -0" rpy="0 0 0" />
      <mass value="0.000496" />
      <inertia ixx="3.679e-09" ixy="-0" ixz="0" iyy="6.779e-09" iyz="-0" izz="5.167e-09" />
    </inertial>
    <!-- Part right_finger3_j1_parts -->
    <visual>
      <origin xyz="0 0.0025 -0" rpy="-3.14159 -1.5708 0" />
      <geometry>
        <mesh filename="../meshes/visual/right_finger3_j1_visual.stl" />
      </geometry>
      <material name="right_finger3_j1_parts_material">
        <color rgba="0.933333 0.933333 0.933333 1" />
      </material>
    </visual>
  </link>
  <!-- Link right_finger3_j2 -->
  <link name="right_finger3_j2">
    <inertial>
      <origin xyz="0 0.015 -0" rpy="0 0 0" />
      <mass value="0.002976" />
      <inertia ixx="2.48e-07" ixy="-0" ixz="0" iyy="4.0672e-08" iyz="-0" izz="2.39072e-07" />
    </inertial>
    <!-- Part right_finger3_j2_parts -->
    <visual>
      <origin xyz="0 0.015 -0" rpy="0 0 -3.14159" />
      <geometry>
        <mesh filename="../meshes/visual/right_finger3_j2_visual.stl" />
      </geometry>
      <material name="right_finger3_j2_parts_material">
        <color rgba="0.933333 0.933333 0.933333 1" />
      </material>
    </visual>
  </link>
  <!-- Link right_finger3_j3 -->
  <link name="right_finger3_j3">
    <inertial>
      <origin xyz="0 0.0125 0" rpy="0 0 0" />
      <mass value="0.001488" />
      <inertia ixx="8.1964e-08" ixy="-0" ixz="-0" iyy="1.24e-08" iyz="0" izz="8.5436e-08" />
    </inertial>
    <!-- Part right_finger3_j3_parts -->
    <visual>
      <origin xyz="0 0.0125 0" rpy="-3.14159 -1.5708 0" />
      <geometry>
        <mesh filename="../meshes/visual/right_finger3_j3_visual.stl" />
      </geometry>
      <material name="right_finger3_j3_parts_material">
        <color rgba="0.933333 0.933333 0.933333 1" />
      </material>
    </visual>
  </link>
  <!-- Link right_finger3_j4 -->
  <link name="right_finger3_j4">
    <inertial>
      <origin xyz="0.000432099 0.00438272 -0" rpy="0 0 0" />
      <mass value="0.0004185" />
      <inertia ixx="3.877e-09" ixy="-6.61e-10" ixz="0" iyy="2.909e-09" iyz="0" izz="5.043e-09" />
    </inertial>
    <!-- Part right_finger3_j4_parts -->
    <visual>
      <origin xyz="0.000432099 0.00438272 -0" rpy="-3.14159 -1.5708 0" />
      <geometry>
        <mesh filename="../meshes/visual/right_finger3_j4_visual.stl" />
      </geometry>
      <material name="right_finger3_j4_parts_material">
        <color rgba="0.933333 0.933333 0.933333 1" />
      </material>
    </visual>
  </link>
  <!-- Joint from right_finger3_j3 to right_finger3_j4 -->
  <joint name="right_finger3_j4" type="revolute">
    <origin xyz="0 0.03 -0" rpy="-0 0 -0" />
    <parent link="right_finger3_j3" />
    <child link="right_finger3_j4" />
    <axis xyz="0 0 1" />
    <limit effort="10" velocity="100" lower="-0.0872665" upper="1.5708" />
    <joint_properties friction="0.1" />
  </joint>
  <!-- Joint from right_finger3_j2 to right_finger3_j3 -->
  <joint name="right_finger3_j3" type="revolute">
    <origin xyz="0 0.035 0" rpy="0 -1.5708 0" />
    <parent link="right_finger3_j2" />
    <child link="right_finger3_j3" />
    <axis xyz="0 0 1" />
    <limit effort="10" velocity="100" lower="-0.0872665" upper="1.91986" />
    <joint_properties friction="0.1" />
  </joint>
  <!-- Joint from right_finger3_j1 to right_finger3_j2 -->
  <joint name="right_finger3_j2" type="revolute">
    <origin xyz="-0 0.01 0" rpy="0 1.5708 0" />
    <parent link="right_finger3_j1" />
    <child link="right_finger3_j2" />
    <axis xyz="0 0 1" />
    <limit effort="10" velocity="100" lower="-0.349066" upper="0.349066" />
    <joint_properties friction="0.1" />
  </joint>
  <!-- Joint from right_hand to right_finger3_j1 -->
  <joint name="right_finger3_j1" type="revolute">
    <origin xyz="0 0.075 -0" rpy="0 0 -0" />
    <parent link="right_hand" />
    <child link="right_finger3_j1" />
    <axis xyz="0 0 1" />
    <limit effort="10" velocity="100" lower="-0.0872665" upper="1.91986" />
    <joint_properties friction="0.1" />
  </joint>
  <!-- Link right_finger4_j1 -->
  <link name="right_finger4_j1">
    <inertial>
      <origin xyz="0 0.0025 0" rpy="0 0 0" />
      <mass value="0.000496" />
      <inertia ixx="3.679e-09" ixy="-0" ixz="0" iyy="6.779e-09" iyz="0" izz="5.167e-09" />
    </inertial>
    <!-- Part right_finger4_j1_parts -->
    <visual>
      <origin xyz="0 0.0025 0" rpy="-3.14159 -1.5708 0" />
      <geometry>
        <mesh filename="../meshes/visual/right_finger4_j1_visual.stl" />
      </geometry>
      <material name="right_finger4_j1_parts_material">
        <color rgba="0.933333 0.933333 0.933333 1" />
      </material>
    </visual>
  </link>
  <!-- Link right_finger4_j2 -->
  <link name="right_finger4_j2">
    <inertial>
      <origin xyz="-0 0.015 0" rpy="0 0 0" />
      <mass value="0.002976" />
      <inertia ixx="2.48e-07" ixy="-0" ixz="-0" iyy="4.0672e-08" iyz="0" izz="2.39072e-07" />
    </inertial>
    <!-- Part right_finger4_j2_parts -->
    <visual>
      <origin xyz="-0 0.015 0" rpy="0 0 -3.14159" />
      <geometry>
        <mesh filename="../meshes/visual/right_finger4_j2_visual.stl" />
      </geometry>
      <material name="right_finger4_j2_parts_material">
        <color rgba="0.933333 0.933333 0.933333 1" />
      </material>
    </visual>
  </link>
  <!-- Link right_finger4_j3 -->
  <link name="right_finger4_j3">
    <inertial>
      <origin xyz="-0 0.01 0" rpy="0 0 0" />
      <mass value="0.0011904" />
      <inertia ixx="4.3251e-08" ixy="0" ixz="-0" iyy="9.92e-09" iyz="-0" izz="4.6029e-08" />
    </inertial>
    <!-- Part right_finger4_j3_parts -->
    <visual>
      <origin xyz="-0 0.01 0" rpy="-3.14159 -1.5708 0" />
      <geometry>
        <mesh filename="../meshes/visual/right_finger4_j3_visual.stl" />
      </geometry>
      <material name="right_finger4_j3_parts_material">
        <color rgba="0.933333 0.933333 0.933333 1" />
      </material>
    </visual>
  </link>
  <!-- Link right_finger4_j4 -->
  <link name="right_finger4_j4">
    <inertial>
      <origin xyz="0.000432099 0.00438272 0" rpy="0 0 0" />
      <mass value="0.0004185" />
      <inertia ixx="3.877e-09" ixy="-6.61e-10" ixz="-0" iyy="2.909e-09" iyz="-0" izz="5.043e-09" />
    </inertial>
    <!-- Part right_finger4_j4_parts -->
    <visual>
      <origin xyz="0.000432099 0.00438272 0" rpy="-3.14159 -1.5708 0" />
      <geometry>
        <mesh filename="../meshes/visual/right_finger4_j4_visual.stl" />
      </geometry>
      <material name="right_finger4_j4_parts_material">
        <color rgba="0.933333 0.933333 0.933333 1" />
      </material>
    </visual>
  </link>
  <!-- Joint from right_finger4_j3 to right_finger4_j4 -->
  <joint name="right_finger4_j4" type="revolute">
    <origin xyz="0 0.025 0" rpy="-0 -0 -0" />
    <parent link="right_finger4_j3" />
    <child link="right_finger4_j4" />
    <axis xyz="0 0 1" />
    <limit effort="10" velocity="100" lower="-0.0872665" upper="1.5708" />
    <joint_properties friction="0.1" />
  </joint>
  <!-- Joint from right_finger4_j2 to right_finger4_j3 -->
  <joint name="right_finger4_j3" type="revolute">
    <origin xyz="0 0.035 0" rpy="0 -1.5708 0" />
    <parent link="right_finger4_j2" />
    <child link="right_finger4_j3" />
    <axis xyz="0 0 1" />
    <limit effort="10" velocity="100" lower="-0.0872665" upper="1.91986" />
    <joint_properties friction="0.1" />
  </joint>
  <!-- Joint from right_finger4_j1 to right_finger4_j2 -->
  <joint name="right_finger4_j2" type="revolute">
    <origin xyz="0 0.01 -0" rpy="-0 1.5708 0" />
    <parent link="right_finger4_j1" />
    <child link="right_finger4_j2" />
    <axis xyz="0 0 1" />
    <limit effort="10" velocity="100" lower="-0.349066" upper="0.349066" />
    <joint_properties friction="0.1" />
  </joint>
  <!-- Joint from right_hand to right_finger4_j1 -->
  <joint name="right_finger4_j1" type="revolute">
    <origin xyz="0 0.07 -0.015" rpy="0 0 -0" />
    <parent link="right_hand" />
    <child link="right_finger4_j1" />
    <axis xyz="0 0 1" />
    <limit effort="10" velocity="100" lower="-0.0872665" upper="1.91986" />
    <joint_properties friction="0.1" />
  </joint>
  <!-- Link right_finger5_j1 -->
  <link name="right_finger5_j1">
    <inertial>
      <origin xyz="0 0.0025 0" rpy="0 0 0" />
      <mass value="0.000496" />
      <inertia ixx="3.679e-09" ixy="0" ixz="0" iyy="6.779e-09" iyz="-0" izz="5.167e-09" />
    </inertial>
    <!-- Part right_finger5_j1_parts -->
    <visual>
      <origin xyz="0 0.0025 0" rpy="-3.14159 -1.5708 0" />
      <geometry>
        <mesh filename="../meshes/visual/right_finger5_j1_visual.stl" />
      </geometry>
      <material name="right_finger5_j1_parts_material">
        <color rgba="0.933333 0.933333 0.933333 1" />
      </material>
    </visual>
  </link>
  <!-- Link right_finger5_j2 -->
  <link name="right_finger5_j2">
    <inertial>
      <origin xyz="-0 0.01 0" rpy="0 0 0" />
      <mass value="0.001984" />
      <inertia ixx="8.2667e-08" ixy="0" ixz="0" iyy="2.7115e-08" iyz="-0" izz="7.6715e-08" />
    </inertial>
    <!-- Part right_finger5_j2_parts -->
    <visual>
      <origin xyz="-0 0.01 0" rpy="0 0 -3.14159" />
      <geometry>
        <mesh filename="../meshes/visual/right_finger5_j2_visual.stl" />
      </geometry>
      <material name="right_finger5_j2_parts_material">
        <color rgba="0.933333 0.933333 0.933333 1" />
      </material>
    </visual>
  </link>
  <!-- Link right_finger5_j3 -->
  <link name="right_finger5_j3">
    <inertial>
      <origin xyz="-0 0.0075 -0" rpy="0 0 0" />
      <mass value="0.0008928" />
      <inertia ixx="1.9418e-08" ixy="-0" ixz="0" iyy="7.44e-09" iyz="-0" izz="2.1502e-08" />
    </inertial>
    <!-- Part right_finger5_j3_parts -->
    <visual>
      <origin xyz="-0 0.0075 -0" rpy="-3.14159 -1.5708 0" />
      <geometry>
        <mesh filename="../meshes/visual/right_finger5_j3_visual.stl" />
      </geometry>
      <material name="right_finger5_j3_parts_material">
        <color rgba="0.933333 0.933333 0.933333 1" />
      </material>
    </visual>
  </link>
  <!-- Link right_finger5_j4 -->
  <link name="right_finger5_j4">
    <inertial>
      <origin xyz="0.000432099 0.00438272 -0" rpy="0 0 0" />
      <mass value="0.0004185" />
      <inertia ixx="3.877e-09" ixy="-6.61e-10" ixz="-0" iyy="2.909e-09" iyz="0" izz="5.043e-09" />
    </inertial>
    <!-- Part right_finger5_j4_parts -->
    <visual>
      <origin xyz="0.000432099 0.00438272 -0" rpy="-3.14159 -1.5708 0" />
      <geometry>
        <mesh filename="../meshes/visual/right_finger5_j4_visual.stl" />
      </geometry>
      <material name="right_finger5_j4_parts_material">
        <color rgba="0.933333 0.933333 0.933333 1" />
      </material>
    </visual>
  </link>
  <!-- Joint from right_finger5_j3 to right_finger5_j4 -->
  <joint name="right_finger5_j4" type="revolute">
    <origin xyz="0 0.02 0" rpy="-0 -0 0" />
    <parent link="right_finger5_j3" />
    <child link="right_finger5_j4" />
    <axis xyz="0 0 1" />
    <limit effort="10" velocity="100" lower="-0.0872665" upper="1.5708" />
    <joint_properties friction="0.1" />
  </joint>
  <!-- Joint from right_finger5_j2 to right_finger5_j3 -->
  <joint name="right_finger5_j3" type="revolute">
    <origin xyz="0 0.025 -0" rpy="-0 -1.5708 0" />
    <parent link="right_finger5_j2" />
    <child link="right_finger5_j3" />
    <axis xyz="0 0 1" />
    <limit effort="10" velocity="100" lower="-0.0872665" upper="1.91986" />
    <joint_properties friction="0.1" />
  </joint>
  <!-- Joint from right_finger5_j1 to right_finger5_j2 -->
  <joint name="right_finger5_j2" type="revolute">
    <origin xyz="0 0.01 0" rpy="0 1.5708 0" />
    <parent link="right_finger5_j1" />
    <child link="right_finger5_j2" />
    <axis xyz="0 0 1" />
    <limit effort="10" velocity="100" lower="-0.349066" upper="0.349066" />
    <joint_properties friction="0.1" />
  </joint>
  <!-- Joint from right_hand to right_finger5_j1 -->
  <joint name="right_finger5_j1" type="revolute">
    <origin xyz="0 0.065 -0.03" rpy="0 0 -0" />
    <parent link="right_hand" />
    <child link="right_finger5_j1" />
    <axis xyz="0 0 1" />
    <limit effort="10" velocity="100" lower="-0.0872665" upper="1.91986" />
    <joint_properties friction="0.1" />
  </joint>
  <!-- Joint from right_wrist_roll to right_hand -->
  <joint name="right_wrist_pitch" type="revolute">
    <origin xyz="0 0 0" rpy="-0 1.5708 0" />
    <parent link="right_wrist_roll" />
    <child link="right_hand" />
    <axis xyz="0 0 1" />
    <limit effort="5.5" velocity="100" lower="-0.785398" upper="0.785398" />
    <joint_properties friction="0.1" />
  </joint>
  <!-- Joint from right_wrist_yaw to right_wrist_roll -->
  <joint name="right_wrist_roll" type="revolute">
    <origin xyz="-0 -0 -0.135" rpy="-1.5708 0 0" />
    <parent link="right_wrist_yaw" />
    <child link="right_wrist_roll" />
    <axis xyz="0 0 1" />
    <limit effort="5.5" velocity="100" lower="-0.698132" upper="0.698132" />
    <joint_properties friction="0.1" />
  </joint>
  <!-- Joint from right_elbow_pitch to right_wrist_yaw -->
  <joint name="right_wrist_yaw" type="revolute">
    <origin xyz="-0.01 0.055 0" rpy="1.5708 -0 -0" />
    <parent link="right_elbow_pitch" />
    <child link="right_wrist_yaw" />
    <axis xyz="0 0 1" />
    <limit effort="5.5" velocity="100" lower="-1.5708" upper="2.0944" />
    <joint_properties friction="0.1" />
  </joint>
  <!-- Joint from right_shoulder_yaw to right_elbow_pitch -->
  <joint name="right_elbow_pitch" type="revolute">
    <origin xyz="0.01 0 -0.08" rpy="-1.5708 -0 0" />
    <parent link="right_shoulder_yaw" />
    <child link="right_elbow_pitch" />
    <axis xyz="0 0 1" />
    <limit effort="14.0" velocity="100" lower="-2.35619" upper="0" />
    <joint_properties friction="0.1" />
  </joint>
  <!-- Joint from right_shoulder_roll to right_shoulder_yaw -->
  <joint name="right_shoulder_yaw" type="revolute">
    <origin xyz="-0 0.12 0" rpy="1.5708 -1.5708 0" />
    <parent link="right_shoulder_roll" />
    <child link="right_shoulder_yaw" />
    <axis xyz="0 0 1" />
    <limit effort="14.0" velocity="100" lower="-1.5708" upper="1.5708" />
    <joint_properties friction="0.1" />
  </joint>
  <!-- Joint from right_shoulder_pitch to right_shoulder_roll -->
  <joint name="right_shoulder_roll" type="revolute">
    <origin xyz="0 0 0" rpy="-1.5708 0.174533 -1.5708" />
    <parent link="right_shoulder_pitch" />
    <child link="right_shoulder_roll" />
    <axis xyz="0 0 1" />
    <limit effort="14.0" velocity="100" lower="-1.91986" upper="1.5708" />
    <joint_properties friction="0.1" />
  </joint>
  <!-- Joint from chest to right_shoulder_pitch -->
  <joint name="right_shoulder_pitch" type="revolute">
    <origin xyz="-0.03 -0.09 0.26" rpy="-1.74533 -0 -0" />
    <parent link="chest" />
    <child link="right_shoulder_pitch" />
    <axis xyz="0 0 1" />
    <limit effort="17.0" velocity="100" lower="-3.14159" upper="0.785398" />
    <joint_properties friction="0.1" />
  </joint>
  <!-- Link neck_yaw -->
  <link name="neck_yaw">
    <inertial>
      <origin xyz="-5.905e-09 -1.3587e-08 0.0703214" rpy="0 0 0" />
      <mass value="0.118449" />
      <inertia ixx="3.32263e-05" ixy="-1.9e-11" ixz="-8e-12" iyy="4.79746e-05" iyz="-4.7e-11" izz="4.39319e-05" />
    </inertial>
    <!-- Part neck_yaw_parts -->
    <visual>
      <origin xyz="-5.905e-09 -1.3587e-08 0.0703214" rpy="-0 -0.174533 -0" />
      <geometry>
        <mesh filename="../meshes/visual/neck_yaw_visual.stl" />
      </geometry>
      <material name="neck_yaw_parts_material">
        <color rgba="0.933333 0.933333 0.933333 1" />
      </material>
    </visual>
  </link>
  <!-- Link neck_roll -->
  <link name="neck_roll">
    <inertial>
      <origin xyz="8.961e-09 0.0398976 -0.0178211" rpy="0 0 0" />
      <mass value="0.144705" />
      <inertia ixx="7.59865e-05" ixy="-3.5e-11" ixz="-2.4e-11" iyy="5.37194e-05" iyz="-1.31631e-05" izz="8.44854e-05" />
    </inertial>
    <!-- Part neck_roll_parts -->
    <visual>
      <origin xyz="8.961e-09 0.0398976 -0.0178211" rpy="3.14159 -1.39626 1.5708" />
      <geometry>
        <mesh filename="../meshes/visual/neck_roll_visual.stl" />
      </geometry>
      <material name="neck_roll_parts_material">
        <color rgba="0.933333 0.933333 0.933333 1" />
      </material>
    </visual>
  </link>
  <!-- Link head -->
  <link name="head">
    <inertial>
      <origin xyz="-0.0136503 0.0084846 -5.43e-10" rpy="0 0 0" />
      <mass value="4.7098" />
      <inertia ixx="0.0192792" ixy="-0.00180799" ixz="-7.2e-11" iyy="0.0157942" iyz="-3e-11" izz="0.0201095" />
    </inertial>
    <!-- Part head_parts -->
    <collision>
      <origin xyz="-0.015 0 0" rpy="-1.5708 -1.5708 0" />
      <geometry>
        <cylinder length="0.03" radius="0.09" />
      </geometry>
    </collision>
    <visual>
      <origin xyz="-0.0136503 0.0084846 -5.43e-10" rpy="1.5708 0 2.96706" />
      <geometry>
        <mesh filename="../meshes/visual/head_visual.stl" />
      </geometry>
      <material name="head_parts_material">
        <color rgba="0.933333 0.933333 0.933333 1" />
      </material>
    </visual>
  </link>
  <!-- Joint from neck_roll to head -->
  <joint name="neck_pitch" type="revolute">
    <origin xyz="0 0.0464025 -0.0132592" rpy="-0 1.5708 0" />
    <parent link="neck_roll" />
    <child link="head" />
    <axis xyz="0 0 1" />
    <limit effort="4.8" velocity="100" lower="-0.698132" upper="0.349066" />
    <joint_properties friction="0.1" />
  </joint>
  <!-- Joint from neck_yaw to neck_roll -->
  <joint name="neck_roll" type="revolute">
    <origin xyz="-0.0125027 -0 0.0709062" rpy="1.5708 0 1.5708" />
    <parent link="neck_yaw" />
    <child link="neck_roll" />
    <axis xyz="0 0 1" />
    <limit effort="4.8" velocity="100" lower="-0.523599" upper="0.523599" />
    <joint_properties friction="0.1" />
  </joint>
  <!-- Joint from chest to neck_yaw -->
  <joint name="neck_yaw" type="revolute">
    <origin xyz="-0.04 0 0.32" rpy="0 0.174533 0" />
    <parent link="chest" />
    <child link="neck_yaw" />
    <axis xyz="0 0 1" />
    <limit effort="4.8" velocity="100" lower="-0.785398" upper="0.785398" />
    <joint_properties friction="0.1" />
  </joint>
  <!-- Joint from pelvis to chest -->
  <joint name="waist_yaw" type="revolute">
    <origin xyz="0.02 -0 0.1" rpy="0 -0 0" />
    <parent link="pelvis" />
    <child link="chest" />
    <axis xyz="0 0 1" />
    <limit effort="36.0" velocity="100" lower="-1.5708" upper="1.5708" />
    <joint_properties friction="0.1" />
  </joint>
</robot>