<?xml version='1.0' encoding='utf-8'?>
<robot name="lite_biped">
  <!-- GENERATED by robot_assets from Onshape CAD. Do not edit by hand. Regenerate: robot-assets-generate lite_biped -->
  <link name="pelvis">
    <inertial>
      <origin xyz="0.0135183 5.78646e-07 0.0691358" rpy="0 0 0" />
      <mass value="3.97182" />
      <inertia ixx="0.0186861" ixy="7.2433e-08" ixz="-0.000228382" iyy="0.015546" iyz="-9.5463e-08" izz="0.0121371" />
    </inertial>
    <!-- Part pelvis_parts -->
    <visual>
      <origin xyz="0.0135183 5.78646e-07 0.0691358" rpy="0 -0 0" />
      <geometry>
        <mesh filename="../meshes/visual/pelvis_visual.stl" />
      </geometry>
      <material name="pelvis_parts_material">
        <color rgba="0.933333 0.933333 0.933333 1" />
      </material>
    </visual>
  </link>
  <!-- Link left_hip_pitch -->
  <link name="left_hip_pitch">
    <inertial>
      <origin xyz="-0.0114774 0.00418673 0.0187959" rpy="0 0 0" />
      <mass value="0.619442" />
      <inertia ixx="0.000652303" ixy="5.37205e-05" ixz="-0.00011886" iyy="0.000778993" iyz="4.47861e-05" izz="0.000986073" />
    </inertial>
    <!-- Part left_hip_pitch_parts -->
    <visual>
      <origin xyz="-0.0114774 0.00418673 0.0187959" rpy="1.74533 0 -0" />
      <geometry>
        <mesh filename="../meshes/visual/left_hip_pitch_visual.stl" />
      </geometry>
      <material name="left_hip_pitch_parts_material">
        <color rgba="0.933333 0.933333 0.933333 1" />
      </material>
    </visual>
  </link>
  <!-- Link left_hip_roll -->
  <link name="left_hip_roll">
    <inertial>
      <origin xyz="-4.8952e-08 0.0525082 -0.0652484" rpy="0 0 0" />
      <mass value="1.30369" />
      <inertia ixx="0.00368883" ixy="-7.197e-09" ixz="4.838e-09" iyy="0.00199601" iyz="-0.000913168" izz="0.00358153" />
    </inertial>
    <!-- Part left_hip_roll_parts -->
    <collision>
      <origin xyz="0 0.181098 -0.0871979" rpy="1.22173 -0 0" />
      <geometry>
        <cylinder length="0.15" radius="0.05" />
      </geometry>
    </collision>
    <visual>
      <origin xyz="-4.8952e-08 0.0525082 -0.0652484" rpy="0 -1.22173 1.5708" />
      <geometry>
        <mesh filename="../meshes/visual/left_hip_roll_visual.stl" />
      </geometry>
      <material name="left_hip_roll_parts_material">
        <color rgba="0.933333 0.933333 0.933333 1" />
      </material>
    </visual>
  </link>
  <!-- Link left_hip_yaw -->
  <link name="left_hip_yaw">
    <inertial>
      <origin xyz="0.00130442 -2.2783e-05 -0.237299" rpy="0 0 0" />
      <mass value="2.08958" />
      <inertia ixx="0.0116205" ixy="1.09303e-06" ixz="-0.000458028" iyy="0.0118686" iyz="2.21073e-07" izz="0.00261694" />
    </inertial>
    <!-- Part left_hip_yaw_parts -->
    <visual>
      <origin xyz="0.00130442 -2.2783e-05 -0.237299" rpy="-0 0 -0" />
      <geometry>
        <mesh filename="../meshes/visual/left_hip_yaw_visual.stl" />
      </geometry>
      <material name="left_hip_yaw_parts_material">
        <color rgba="0.933333 0.933333 0.933333 1" />
      </material>
    </visual>
  </link>
  <!-- Link left_knee_pitch -->
  <link name="left_knee_pitch">
    <inertial>
      <origin xyz="-0.00486713 0.0372163 -0.000224083" rpy="0 0 0" />
      <mass value="0.435399" />
      <inertia ixx="0.000913317" ixy="6.65453e-05" ixz="-2.2735e-07" iyy="0.000625586" iyz="1.07178e-06" izz="0.000714736" />
    </inertial>
    <!-- Part left_knee_pitch_parts -->
    <collision>
      <origin xyz="-0.015 0.19 0" rpy="1.5708 1.5708 0" />
      <geometry>
        <cylinder length="0.12" radius="0.045" />
      </geometry>
    </collision>
    <visual>
      <origin xyz="-0.00486713 0.0372163 -0.000224083" rpy="1.5708 0 0" />
      <geometry>
        <mesh filename="../meshes/visual/left_knee_pitch_visual.stl" />
      </geometry>
      <material name="left_knee_pitch_parts_material">
        <color rgba="0.933333 0.933333 0.933333 1" />
      </material>
    </visual>
  </link>
  <!-- Link left_ankle_yaw -->
  <link name="left_ankle_yaw">
    <inertial>
      <origin xyz="-0.00304992 0.00150525 -0.18535" rpy="0 0 0" />
      <mass value="1.43174" />
      <inertia ixx="0.00763083" ixy="3.0411e-06" ixz="0.000159775" iyy="0.00768647" iyz="-2.6083e-05" izz="0.00115305" />
    </inertial>
    <!-- Part left_ankle_yaw_parts -->
    <visual>
      <origin xyz="-0.00304992 0.00150525 -0.18535" rpy="-0 0 -0" />
      <geometry>
        <mesh filename="../meshes/visual/left_ankle_yaw_visual.stl" />
      </geometry>
      <material name="left_ankle_yaw_parts_material">
        <color rgba="0.933333 0.933333 0.933333 1" />
      </material>
    </visual>
  </link>
  <!-- Link left_ankle_pitch -->
  <link name="left_ankle_pitch">
    <inertial>
      <origin xyz="-0.00384209 0.0297371 3.1356e-08" rpy="0 0 0" />
      <mass value="0.184118" />
      <inertia ixx="9.75514e-05" ixy="-1.6796e-05" ixz="-4.2e-11" iyy="7.7573e-05" iyz="1.44e-10" izz="0.00013275" />
    </inertial>
    <!-- Part left_ankle_pitch_parts -->
    <visual>
      <origin xyz="-0.00384209 0.0297371 3.1356e-08" rpy="1.5708 -0 -0" />
      <geometry>
        <mesh filename="../meshes/visual/left_ankle_pitch_visual.stl" />
      </geometry>
      <material name="left_ankle_pitch_parts_material">
        <color rgba="0.933333 0.933333 0.933333 1" />
      </material>
    </visual>
  </link>
  <!-- Link left_foot -->
  <link name="left_foot">
    <inertial>
      <origin xyz="0.00124938 0.0227876 0.0398042" rpy="0 0 0" />
      <mass value="1.20654" />
      <inertia ixx="0.00367026" ixy="-9.09996e-06" ixz="-0.000117811" iyy="0.00327589" iyz="-0.000424612" izz="0.00132106" />
    </inertial>
    <!-- Part left_foot_parts -->
    <collision>
      <origin xyz="0 0.05 0.015" rpy="1.5708 0 0" />
      <geometry>
        <box size="0.065 0.12 0.03" />
      </geometry>
    </collision>
    <collision>
      <origin xyz="0 0.04 0.11" rpy="1.91986 0 0" />
      <geometry>
        <box size="0.07 0.05 0.03" />
      </geometry>
    </collision>
    <visual>
      <origin xyz="0.00124938 0.0227876 0.0398042" rpy="1.5708 -1.5708 0" />
      <geometry>
        <mesh filename="../meshes/visual/left_foot_visual.stl" />
      </geometry>
      <material name="left_foot_parts_material">
        <color rgba="0.933333 0.933333 0.933333 1" />
      </material>
    </visual>
  </link>
  <!-- Joint from left_ankle_pitch to left_foot -->
  <joint name="left_ankle_roll" type="revolute">
    <origin xyz="-0 0.04 0" rpy="0 1.5708 0" />
    <parent link="left_ankle_pitch" />
    <child link="left_foot" />
    <axis xyz="0 0 1" />
    <limit effort="5.5" velocity="100" lower="-0.349066" upper="0.349066" />
    <joint_properties friction="0.1" />
  </joint>
  <!-- Joint from left_ankle_yaw to left_ankle_pitch -->
  <joint name="left_ankle_pitch" type="revolute">
    <origin xyz="0.01 -0 -0.34" rpy="-1.5708 0 -0" />
    <parent link="left_ankle_yaw" />
    <child link="left_ankle_pitch" />
    <axis xyz="0 0 1" />
    <limit effort="14.0" velocity="100" lower="-0.523599" upper="0.872665" />
    <joint_properties friction="0.1" />
  </joint>
  <!-- Joint from left_knee_pitch to left_ankle_yaw -->
  <joint name="left_ankle_yaw" type="revolute">
    <origin xyz="-0.015 0 0" rpy="1.5708 0 -0" />
    <parent link="left_knee_pitch" />
    <child link="left_ankle_yaw" />
    <axis xyz="0 0 1" />
    <limit effort="14.0" velocity="100" lower="-0.785398" upper="0.785398" />
    <joint_properties friction="0.1" />
  </joint>
  <!-- Joint from left_hip_yaw to left_knee_pitch -->
  <joint name="left_knee_pitch" type="revolute">
    <origin xyz="-0.01 0 -0.33" rpy="-1.5708 0 0" />
    <parent link="left_hip_yaw" />
    <child link="left_knee_pitch" />
    <axis xyz="0 0 1" />
    <limit effort="36.0" velocity="100" lower="0" upper="2.35619" />
    <joint_properties friction="0.1" />
  </joint>
  <!-- Joint from left_hip_roll to left_hip_yaw -->
  <joint name="left_hip_yaw" type="revolute">
    <origin xyz="0 -0.0068404 -0.0187939" rpy="0 -1.22173 1.5708" />
    <parent link="left_hip_roll" />
    <child link="left_hip_yaw" />
    <axis xyz="0 0 1" />
    <limit effort="17.0" velocity="100" lower="-1.5708" upper="1.5708" />
    <joint_properties friction="0.1" />
  </joint>
  <!-- Joint from left_hip_pitch to left_hip_roll -->
  <joint name="left_hip_roll" type="revolute">
    <origin xyz="-0 0 -0" rpy="1.91986 1.39626 1.5708" />
    <parent link="left_hip_pitch" />
    <child link="left_hip_roll" />
    <axis xyz="0 0 1" />
    <limit effort="36.0" velocity="100" lower="-0.349066" upper="1.5708" />
    <joint_properties friction="0.1" />
  </joint>
  <!-- Joint from pelvis to left_hip_pitch -->
  <joint name="left_hip_pitch" type="revolute">
    <origin xyz="0.02 0.07 0" rpy="-1.74533 0 0" />
    <parent link="pelvis" />
    <child link="left_hip_pitch" />
    <axis xyz="0 0 1" />
    <limit effort="36.0" velocity="100" lower="-2.35619" upper="0.785398" />
    <joint_properties friction="0.1" />
  </joint>
  <!-- Link right_hip_pitch -->
  <link name="right_hip_pitch">
    <inertial>
      <origin xyz="-0.0114771 0.00418737 -0.0187964" rpy="0 0 0" />
      <mass value="0.619423" />
      <inertia ixx="0.000652275" ixy="5.37438e-05" ixz="0.000118863" iyy="0.000778995" iyz="-4.4778e-05" izz="0.000986036" />
    </inertial>
    <!-- Part right_hip_pitch_parts -->
    <visual>
      <origin xyz="-0.0114771 0.00418737 -0.0187964" rpy="1.39626 0 -0" />
      <geometry>
        <mesh filename="../meshes/visual/right_hip_pitch_visual.stl" />
      </geometry>
      <material name="right_hip_pitch_parts_material">
        <color rgba="0.933333 0.933333 0.933333 1" />
      </material>
    </visual>
  </link>
  <!-- Link right_hip_roll -->
  <link name="right_hip_roll">
    <inertial>
      <origin xyz="-1.13349e-07 0.0525083 -0.0652488" rpy="0 0 0" />
      <mass value="1.30368" />
      <inertia ixx="0.0036888" ixy="3.8e-10" ixz="8.521e-09" iyy="0.00199598" iyz="-0.000913166" izz="0.0035815" />
    </inertial>
    <!-- Part right_hip_roll_parts -->
    <collision>
      <origin xyz="-0 0.181098 -0.0871979" rpy="1.22173 0 0" />
      <geometry>
        <cylinder length="0.15" radius="0.05" />
      </geometry>
    </collision>
    <visual>
      <origin xyz="-1.13349e-07 0.0525083 -0.0652488" rpy="0 -1.22173 1.5708" />
      <geometry>
        <mesh filename="../meshes/visual/right_hip_roll_visual.stl" />
      </geometry>
      <material name="right_hip_roll_parts_material">
        <color rgba="0.933333 0.933333 0.933333 1" />
      </material>
    </visual>
  </link>
  <!-- Link right_hip_yaw -->
  <link name="right_hip_yaw">
    <inertial>
      <origin xyz="0.00130421 2.35733e-05 -0.237299" rpy="0 0 0" />
      <mass value="2.08959" />
      <inertia ixx="0.0116206" ixy="-1.08279e-06" ixz="-0.000458016" iyy="0.0118687" iyz="-3.03522e-07" izz="0.00261696" />
    </inertial>
    <!-- Part right_hip_yaw_parts -->
    <visual>
      <origin xyz="0.00130421 2.35733e-05 -0.237299" rpy="0 0 0" />
      <geometry>
        <mesh filename="../meshes/visual/right_hip_yaw_visual.stl" />
      </geometry>
      <material name="right_hip_yaw_parts_material">
        <color rgba="0.933333 0.933333 0.933333 1" />
      </material>
    </visual>
  </link>
  <!-- Link right_knee_pitch -->
  <link name="right_knee_pitch">
    <inertial>
      <origin xyz="-0.0048642 0.0372186 0.000224747" rpy="0 0 0" />
      <mass value="0.435358" />
      <inertia ixx="0.000913266" ixy="6.65739e-05" ixz="2.14089e-07" iyy="0.000625521" iyz="-1.04876e-06" izz="0.00071467" />
    </inertial>
    <!-- Part right_knee_pitch_parts -->
    <collision>
      <origin xyz="-0.015 0.19 0" rpy="1.5708 1.5708 0" />
      <geometry>
        <cylinder length="0.12" radius="0.045" />
      </geometry>
    </collision>
    <visual>
      <origin xyz="-0.0048642 0.0372186 0.000224747" rpy="1.5708 -0 0" />
      <geometry>
        <mesh filename="../meshes/visual/right_knee_pitch_visual.stl" />
      </geometry>
      <material name="right_knee_pitch_parts_material">
        <color rgba="0.933333 0.933333 0.933333 1" />
      </material>
    </visual>
  </link>
  <!-- Link right_ankle_yaw -->
  <link name="right_ankle_yaw">
    <inertial>
      <origin xyz="-0.00304908 -0.0015054 -0.185348" rpy="0 0 0" />
      <mass value="1.43169" />
      <inertia ixx="0.00763064" ixy="-3.05072e-06" ixz="0.000159784" iyy="0.00768622" iyz="2.60897e-05" izz="0.00115301" />
    </inertial>
    <!-- Part right_ankle_yaw_parts -->
    <visual>
      <origin xyz="-0.00304908 -0.0015054 -0.185348" rpy="-0 0 0" />
      <geometry>
        <mesh filename="../meshes/visual/right_ankle_yaw_visual.stl" />
      </geometry>
      <material name="right_ankle_yaw_parts_material">
        <color rgba="0.933333 0.933333 0.933333 1" />
      </material>
    </visual>
  </link>
  <!-- Link right_ankle_pitch -->
  <link name="right_ankle_pitch">
    <inertial>
      <origin xyz="-0.00384209 0.0297371 3.1396e-08" rpy="0 0 0" />
      <mass value="0.184118" />
      <inertia ixx="9.75514e-05" ixy="-1.6796e-05" ixz="-4.2e-11" iyy="7.7573e-05" iyz="1.44e-10" izz="0.00013275" />
    </inertial>
    <!-- Part right_ankle_pitch_parts -->
    <visual>
      <origin xyz="-0.00384209 0.0297371 3.1396e-08" rpy="1.5708 -0 0" />
      <geometry>
        <mesh filename="../meshes/visual/right_ankle_pitch_visual.stl" />
      </geometry>
      <material name="right_ankle_pitch_parts_material">
        <color rgba="0.933333 0.933333 0.933333 1" />
      </material>
    </visual>
  </link>
  <!-- Link right_foot -->
  <link name="right_foot">
    <inertial>
      <origin xyz="-0.0012494 0.0227876 0.039804" rpy="0 0 0" />
      <mass value="1.20654" />
      <inertia ixx="0.00367026" ixy="9.09895e-06" ixz="0.000117812" iyy="0.00327589" iyz="-0.000424612" izz="0.00132106" />
    </inertial>
    <!-- Part right_foot_parts -->
    <collision>
      <origin xyz="0 0.05 0.015" rpy="1.5708 0 -0" />
      <geometry>
        <box size="0.065 0.12 0.03" />
      </geometry>
    </collision>
    <collision>
      <origin xyz="0 0.04 0.11" rpy="1.91986 0 -0" />
      <geometry>
        <box size="0.07 0.05 0.03" />
      </geometry>
    </collision>
    <visual>
      <origin xyz="-0.0012494 0.0227876 0.039804" rpy="1.5708 -1.5708 0" />
      <geometry>
        <mesh filename="../meshes/visual/right_foot_visual.stl" />
      </geometry>
      <material name="right_foot_parts_material">
        <color rgba="0.933333 0.933333 0.933333 1" />
      </material>
    </visual>
  </link>
  <!-- Joint from right_ankle_pitch to right_foot -->
  <joint name="right_ankle_roll" type="revolute">
    <origin xyz="0 0.04 0" rpy="0 1.5708 0" />
    <parent link="right_ankle_pitch" />
    <child link="right_foot" />
    <axis xyz="0 0 1" />
    <limit effort="5.5" velocity="100" lower="-0.349066" upper="0.349066" />
    <joint_properties friction="0.1" />
  </joint>
  <!-- Joint from right_ankle_yaw to right_ankle_pitch -->
  <joint name="right_ankle_pitch" type="revolute">
    <origin xyz="0.01 0 -0.34" rpy="-1.5708 -0 -0" />
    <parent link="right_ankle_yaw" />
    <child link="right_ankle_pitch" />
    <axis xyz="0 0 1" />
    <limit effort="14.0" velocity="100" lower="-0.523599" upper="0.872665" />
    <joint_properties friction="0.1" />
  </joint>
  <!-- Joint from right_knee_pitch to right_ankle_yaw -->
  <joint name="right_ankle_yaw" type="revolute">
    <origin xyz="-0.015 0 0" rpy="1.5708 -0 -0" />
    <parent link="right_knee_pitch" />
    <child link="right_ankle_yaw" />
    <axis xyz="0 0 1" />
    <limit effort="14.0" velocity="100" lower="-0.785398" upper="0.785398" />
    <joint_properties friction="0.1" />
  </joint>
  <!-- Joint from right_hip_yaw to right_knee_pitch -->
  <joint name="right_knee_pitch" type="revolute">
    <origin xyz="-0.01 -0 -0.33" rpy="-1.5708 0 -0" />
    <parent link="right_hip_yaw" />
    <child link="right_knee_pitch" />
    <axis xyz="0 0 1" />
    <limit effort="36.0" velocity="100" lower="0" upper="2.35619" />
    <joint_properties friction="0.1" />
  </joint>
  <!-- Joint from right_hip_roll to right_hip_yaw -->
  <joint name="right_hip_yaw" type="revolute">
    <origin xyz="0 -0.0068404 -0.0187939" rpy="0 -1.22173 1.5708" />
    <parent link="right_hip_roll" />
    <child link="right_hip_yaw" />
    <axis xyz="0 0 1" />
    <limit effort="17.0" velocity="100" lower="-1.5708" upper="1.5708" />
    <joint_properties friction="0.1" />
  </joint>
  <!-- Joint from right_hip_pitch to right_hip_roll -->
  <joint name="right_hip_roll" type="revolute">
    <origin xyz="0 -0 -0" rpy="-1.22173 1.39626 -1.5708" />
    <parent link="right_hip_pitch" />
    <child link="right_hip_roll" />
    <axis xyz="0 0 1" />
    <limit effort="36.0" velocity="100" lower="-1.5708" upper="0.349066" />
    <joint_properties friction="0.1" />
  </joint>
  <!-- Joint from pelvis to right_hip_pitch -->
  <joint name="right_hip_pitch" type="revolute">
    <origin xyz="0.02 -0.07 -0" rpy="-1.39626 -0 0" />
    <parent link="pelvis" />
    <child link="right_hip_pitch" />
    <axis xyz="0 0 1" />
    <limit effort="36.0" velocity="100" lower="-2.35619" upper="0.785398" />
    <joint_properties friction="0.1" />
  </joint>
</robot>