<?xml version='1.0' encoding='utf-8'?>
<robot name="lite_bimanual">
  <!-- GENERATED by robot_assets from Onshape CAD. Do not edit by hand. Regenerate: robot-assets-generate lite_bimanual -->
  <link name="chest">
    <inertial>
      <origin xyz="0.0223994 -6.1147e-08 0.218844" rpy="0 0 0" />
      <mass value="5.67528" />
      <inertia ixx="0.11598" ixy="1.60807e-07" ixz="-0.0169372" iyy="0.116403" iyz="6.26784e-07" izz="0.0554604" />
    </inertial>
    <!-- Part chest_parts -->
    <collision>
      <origin xyz="0.055 0 0.18" rpy="0.226893 0 -1.5708" />
      <geometry>
        <cylinder length="0.16" radius="0.053" />
      </geometry>
    </collision>
    <collision>
      <origin xyz="0.045 -0.04 0.22" rpy="0.226893 -0.174533 -1.5708" />
      <geometry>
        <box size="0.04 0.08 0.18" />
      </geometry>
    </collision>
    <collision>
      <origin xyz="0.045 0.04 0.22" rpy="0.226893 0.174533 -1.5708" />
      <geometry>
        <box size="0.04 0.08 0.18" />
      </geometry>
    </collision>
    <visual>
      <origin xyz="0.0223994 -6.1147e-08 0.218844" rpy="0 -0 0" />
      <geometry>
        <mesh filename="../meshes/visual/chest_visual.stl" />
      </geometry>
      <material name="chest_parts_material">
        <color rgba="0.877556 0.877556 0.877556 1" />
      </material>
    </visual>
  </link>
  <!-- Link left_shoulder_pitch -->
  <link name="left_shoulder_pitch">
    <inertial>
      <origin xyz="-6.27e-10 -0.00168619 -0.00682299" rpy="0 0 0" />
      <mass value="0.375" />
      <inertia ixx="0.000232695" ixy="7e-12" ixz="2e-12" iyy="0.000233203" iyz="-1.40823e-05" izz="0.000199827" />
    </inertial>
    <!-- Part left_shoulder_pitch_parts -->
    <visual>
      <origin xyz="-6.27e-10 -0.00168619 -0.00682299" rpy="1.39626 0 -0" />
      <geometry>
        <mesh filename="../meshes/visual/left_shoulder_pitch_visual.stl" />
      </geometry>
      <material name="left_shoulder_pitch_parts_material">
        <color rgba="0.933333 0.933333 0.933333 1" />
      </material>
    </visual>
  </link>
  <!-- Link left_shoulder_roll -->
  <link name="left_shoulder_roll">
    <inertial>
      <origin xyz="1.04497e-07 0.0788914 2.17586e-07" rpy="0 0 0" />
      <mass value="0.42" />
      <inertia ixx="0.000535467" ixy="-2.373e-09" ixz="5.049e-09" iyy="0.000208176" iyz="7.18e-09" izz="0.00050471" />
    </inertial>
    <!-- Part left_shoulder_roll_parts -->
    <visual>
      <origin xyz="1.04497e-07 0.0788914 2.17586e-07" rpy="0 -1.5708 0" />
      <geometry>
        <mesh filename="../meshes/visual/left_shoulder_roll_visual.stl" />
      </geometry>
      <material name="left_shoulder_roll_parts_material">
        <color rgba="0.392063 0.392063 0.392063 1" />
      </material>
    </visual>
  </link>
  <!-- Link left_shoulder_yaw -->
  <link name="left_shoulder_yaw">
    <inertial>
      <origin xyz="0.00503665 -3.0465e-08 -0.0550993" rpy="0 0 0" />
      <mass value="0.43" />
      <inertia ixx="0.000494513" ixy="-1.96e-10" ixz="4.80344e-05" iyy="0.000498656" iyz="9.95e-10" izz="0.000218184" />
    </inertial>
    <!-- Part left_shoulder_yaw_parts -->
    <collision>
      <origin xyz="0 0 0.06" rpy="3.14159 -0 1.5708" />
      <geometry>
        <cylinder length="0.12" radius="0.035" />
      </geometry>
    </collision>
    <visual>
      <origin xyz="0.00503665 -3.0465e-08 -0.0550993" rpy="-1.5708 -0 0" />
      <geometry>
        <mesh filename="../meshes/visual/left_shoulder_yaw_visual.stl" />
      </geometry>
      <material name="left_shoulder_yaw_parts_material">
        <color rgba="0.933333 0.933333 0.933333 1" />
      </material>
    </visual>
  </link>
  <!-- Link left_elbow_pitch -->
  <link name="left_elbow_pitch">
    <inertial>
      <origin xyz="-0.00956573 0.0258355 -2.70123e-07" rpy="0 0 0" />
      <mass value="0.11" />
      <inertia ixx="0.000116342" ixy="7.43616e-06" ixz="-4.1438e-08" iyy="9.70555e-05" iyz="-5.662e-09" izz="7.93924e-05" />
    </inertial>
    <!-- Part left_elbow_pitch_parts -->
    <visual>
      <origin xyz="-0.00956573 0.0258355 -2.70123e-07" rpy="0 -0 -0" />
      <geometry>
        <mesh filename="../meshes/visual/left_elbow_pitch_visual.stl" />
      </geometry>
      <material name="left_elbow_pitch_parts_material">
        <color rgba="0.933333 0.933333 0.933333 1" />
      </material>
    </visual>
  </link>
  <!-- Link left_wrist_yaw -->
  <link name="left_wrist_yaw">
    <inertial>
      <origin xyz="1.26198e-07 -2.64771e-05 -0.0592502" rpy="0 0 0" />
      <mass value="0.54" />
      <inertia ixx="0.000850281" ixy="-2.7403e-08" ixz="-4.21e-09" iyy="0.000856128" iyz="-4.1398e-08" izz="0.000282296" />
    </inertial>
    <!-- Part left_wrist_yaw_parts -->
    <collision>
      <origin xyz="-0 -0 -0.04" rpy="0 0 0" />
      <geometry>
        <cylinder length="0.19" radius="0.03" />
      </geometry>
    </collision>
    <visual>
      <origin xyz="1.26198e-07 -2.64771e-05 -0.0592502" rpy="-1.5708 -0 -0" />
      <geometry>
        <mesh filename="../meshes/visual/left_wrist_yaw_visual.stl" />
      </geometry>
      <material name="left_wrist_yaw_parts_material">
        <color rgba="0.933333 0.933333 0.933333 1" />
      </material>
    </visual>
  </link>
  <!-- Link left_wrist_roll -->
  <link name="left_wrist_roll">
    <inertial>
      <origin xyz="3.48e-10 1e-12 -2.12e-10" rpy="0 0 0" />
      <mass value="0.25" />
      <inertia ixx="7.92687e-05" ixy="0" ixz="0" iyy="9.19125e-05" iyz="-6.7e-11" izz="9.04076e-05" />
    </inertial>
    <!-- Part left_wrist_roll_parts -->
    <visual>
      <origin xyz="3.48e-10 1e-12 -2.12e-10" rpy="0 0 -0" />
      <geometry>
        <mesh filename="../meshes/visual/left_wrist_roll_visual.stl" />
      </geometry>
      <material name="left_wrist_roll_parts_material">
        <color rgba="0.933333 0.933333 0.933333 1" />
      </material>
    </visual>
  </link>
  <!-- Link left_hand -->
  <link name="left_hand">
    <inertial>
      <origin xyz="0.0044138 0.1008 0.00606018" rpy="0 0 0" />
      <mass value="0.167493" />
      <inertia ixx="0.000456305" ixy="-6.09198e-07" ixz="-6.11506e-07" iyy="9.83135e-05" iyz="-4.35308e-05" izz="0.000407599" />
    </inertial>
    <!-- Part left_hand_parts -->
    <collision>
      <origin xyz="-0.007 0.194 0.0225" rpy="1.5708 1.5708 0" />
      <geometry>
        <cylinder length="0.06" radius="0.006" />
      </geometry>
    </collision>
    <collision>
      <origin xyz="0.01 0.1 0.0005" rpy="1.5708 1.5708 0" />
      <geometry>
        <cylinder length="0.04" radius="0.035" />
      </geometry>
    </collision>
    <visual>
      <origin xyz="0.0044138 0.1008 0.00606018" rpy="-0 -1.5708 0" />
      <geometry>
        <mesh filename="../meshes/visual/left_hand_visual.stl" />
      </geometry>
      <material name="left_hand_parts_material">
        <color rgba="0.935303 0.913041 0.886642 1" />
      </material>
    </visual>
  </link>
  <!-- Frame left_finger2_tip (dummy link + fixed joint) -->
  <link name="left_finger2_tip">
    <origin xyz="0 0 0" rpy="0 -0 0" />
    <inertial>
      <origin xyz="0 0 0" rpy="0 0 0" />
      <mass value="1e-9" />
      <inertia ixx="0" ixy="0" ixz="0" iyy="0" iyz="0" izz="0" />
    </inertial>
  </link>
  <joint name="left_finger2_tip_frame" type="fixed">
    <origin xyz="-0.007 0.225 0.0225" rpy="-1.5708 -0 1.5708" />
    <parent link="left_hand" />
    <child link="left_finger2_tip" />
    <axis xyz="0 0 0" />
  </joint>
  <!-- Joint from left_wrist_roll to left_hand -->
  <joint name="left_wrist_pitch" type="revolute">
    <origin xyz="0 -0 -0" rpy="0 1.5708 0" />
    <parent link="left_wrist_roll" />
    <child link="left_hand" />
    <axis xyz="0 0 1" />
    <limit effort="5.5" velocity="100" lower="-0.785398" upper="0.785398" />
    <joint_properties friction="0.1" />
  </joint>
  <!-- Joint from left_wrist_yaw to left_wrist_roll -->
  <joint name="left_wrist_roll" type="revolute">
    <origin xyz="0 0 -0.135" rpy="-1.5708 0 -0" />
    <parent link="left_wrist_yaw" />
    <child link="left_wrist_roll" />
    <axis xyz="0 0 1" />
    <limit effort="5.5" velocity="100" lower="-0.698132" upper="0.698132" />
    <joint_properties friction="0.1" />
  </joint>
  <!-- Joint from left_elbow_pitch to left_wrist_yaw -->
  <joint name="left_wrist_yaw" type="revolute">
    <origin xyz="-0.01 0.055 0" rpy="1.5708 -0 -0" />
    <parent link="left_elbow_pitch" />
    <child link="left_wrist_yaw" />
    <axis xyz="0 0 1" />
    <limit effort="5.5" velocity="100" lower="-2.0944" upper="1.5708" />
    <joint_properties friction="0.1" />
  </joint>
  <!-- Joint from left_shoulder_yaw to left_elbow_pitch -->
  <joint name="left_elbow_pitch" type="revolute">
    <origin xyz="0.01 -0 -0.08" rpy="-1.5708 0 0" />
    <parent link="left_shoulder_yaw" />
    <child link="left_elbow_pitch" />
    <axis xyz="0 0 1" />
    <limit effort="14" velocity="100" lower="-2.35619" upper="0" />
    <joint_properties friction="0.1" />
  </joint>
  <!-- Joint from left_shoulder_roll to left_shoulder_yaw -->
  <joint name="left_shoulder_yaw" type="revolute">
    <origin xyz="0 0.12 0" rpy="1.5708 -1.5708 0" />
    <parent link="left_shoulder_roll" />
    <child link="left_shoulder_yaw" />
    <axis xyz="0 0 1" />
    <limit effort="14" velocity="100" lower="-1.5708" upper="1.5708" />
    <joint_properties friction="0.1" />
  </joint>
  <!-- Joint from left_shoulder_pitch to left_shoulder_roll -->
  <joint name="left_shoulder_roll" type="revolute">
    <origin xyz="0 -0 0" rpy="1.5708 0.174533 1.5708" />
    <parent link="left_shoulder_pitch" />
    <child link="left_shoulder_roll" />
    <axis xyz="0 0 1" />
    <limit effort="14" velocity="100" lower="-1.5708" upper="1.91986" />
    <joint_properties friction="0.1" />
  </joint>
  <!-- Joint from chest to left_shoulder_pitch -->
  <joint name="left_shoulder_pitch" type="revolute">
    <origin xyz="0.02 0.09 0.36" rpy="-1.39626 0 0" />
    <parent link="chest" />
    <child link="left_shoulder_pitch" />
    <axis xyz="0 0 1" />
    <limit effort="17" velocity="100" lower="-3.14159" upper="0.785398" />
    <joint_properties friction="0.1" />
  </joint>
  <!-- Link right_shoulder_pitch -->
  <link name="right_shoulder_pitch">
    <inertial>
      <origin xyz="6.27e-10 -0.00168619 0.00682299" rpy="0 0 0" />
      <mass value="0.375" />
      <inertia ixx="0.000232695" ixy="-7e-12" ixz="2e-12" iyy="0.000233203" iyz="1.40823e-05" izz="0.000199827" />
    </inertial>
    <!-- Part right_shoulder_pitch_parts -->
    <visual>
      <origin xyz="6.27e-10 -0.00168619 0.00682299" rpy="1.74533 0 0" />
      <geometry>
        <mesh filename="../meshes/visual/right_shoulder_pitch_visual.stl" />
      </geometry>
      <material name="right_shoulder_pitch_parts_material">
        <color rgba="0.933333 0.933333 0.933333 1" />
      </material>
    </visual>
  </link>
  <!-- Link right_shoulder_roll -->
  <link name="right_shoulder_roll">
    <inertial>
      <origin xyz="-1.01172e-07 0.0788914 2.6114e-08" rpy="0 0 0" />
      <mass value="0.42" />
      <inertia ixx="0.000535466" ixy="2.667e-09" ixz="-3.953e-09" iyy="0.000208176" iyz="-1.3e-11" izz="0.00050471" />
    </inertial>
    <!-- Part right_shoulder_roll_parts -->
    <visual>
      <origin xyz="-1.01172e-07 0.0788914 2.6114e-08" rpy="-3.14159 -1.5708 0" />
      <geometry>
        <mesh filename="../meshes/visual/right_shoulder_roll_visual.stl" />
      </geometry>
      <material name="right_shoulder_roll_parts_material">
        <color rgba="0.392063 0.392063 0.392063 1" />
      </material>
    </visual>
  </link>
  <!-- Link right_shoulder_yaw -->
  <link name="right_shoulder_yaw">
    <inertial>
      <origin xyz="0.00503646 -5.8721e-08 -0.0550993" rpy="0 0 0" />
      <mass value="0.43" />
      <inertia ixx="0.000494516" ixy="1.11e-10" ixz="4.80353e-05" iyy="0.000498658" iyz="1.121e-09" izz="0.000218183" />
    </inertial>
    <!-- Part right_shoulder_yaw_parts -->
    <collision>
      <origin xyz="0 -0 0.06" rpy="3.14159 0 1.5708" />
      <geometry>
        <cylinder length="0.12" radius="0.035" />
      </geometry>
    </collision>
    <visual>
      <origin xyz="0.00503646 -5.8721e-08 -0.0550993" rpy="1.5708 0 0" />
      <geometry>
        <mesh filename="../meshes/visual/right_shoulder_yaw_visual.stl" />
      </geometry>
      <material name="right_shoulder_yaw_parts_material">
        <color rgba="0.933333 0.933333 0.933333 1" />
      </material>
    </visual>
  </link>
  <!-- Link right_elbow_pitch -->
  <link name="right_elbow_pitch">
    <inertial>
      <origin xyz="-0.0095654 0.0258358 1.46047e-06" rpy="0 0 0" />
      <mass value="0.11" />
      <inertia ixx="0.000116343" ixy="7.43678e-06" ixz="3.8036e-08" iyy="9.70569e-05" iyz="6.815e-09" izz="7.93932e-05" />
    </inertial>
    <!-- Part right_elbow_pitch_parts -->
    <visual>
      <origin xyz="-0.0095654 0.0258358 1.46047e-06" rpy="-3.14159 -0 0" />
      <geometry>
        <mesh filename="../meshes/visual/right_elbow_pitch_visual.stl" />
      </geometry>
      <material name="right_elbow_pitch_parts_material">
        <color rgba="0.933333 0.933333 0.933333 1" />
      </material>
    </visual>
  </link>
  <!-- Link right_wrist_yaw -->
  <link name="right_wrist_yaw">
    <inertial>
      <origin xyz="1.99324e-07 2.65767e-05 -0.0592501" rpy="0 0 0" />
      <mass value="0.54" />
      <inertia ixx="0.000850282" ixy="2.867e-08" ixz="-3.809e-09" iyy="0.000856128" iyz="4.2812e-08" izz="0.000282295" />
    </inertial>
    <!-- Part right_wrist_yaw_parts -->
    <collision>
      <origin xyz="-0 -0 -0.04" rpy="-0 0 3.14159" />
      <geometry>
        <cylinder length="0.19" radius="0.03" />
      </geometry>
    </collision>
    <visual>
      <origin xyz="1.99324e-07 2.65767e-05 -0.0592501" rpy="1.5708 0 0" />
      <geometry>
        <mesh filename="../meshes/visual/right_wrist_yaw_visual.stl" />
      </geometry>
      <material name="right_wrist_yaw_parts_material">
        <color rgba="0.933333 0.933333 0.933333 1" />
      </material>
    </visual>
  </link>
  <!-- Link right_wrist_roll -->
  <link name="right_wrist_roll">
    <inertial>
      <origin xyz="4.084e-09 -2e-12 -2.02e-10" rpy="0 0 0" />
      <mass value="0.25" />
      <inertia ixx="7.92688e-05" ixy="-0" ixz="0" iyy="9.19094e-05" iyz="2.493e-09" izz="9.04084e-05" />
    </inertial>
    <!-- Part right_wrist_roll_parts -->
    <visual>
      <origin xyz="4.084e-09 -2e-12 -2.02e-10" rpy="-3.14159 -0 0" />
      <geometry>
        <mesh filename="../meshes/visual/right_wrist_roll_visual.stl" />
      </geometry>
      <material name="right_wrist_roll_parts_material">
        <color rgba="0.933333 0.933333 0.933333 1" />
      </material>
    </visual>
  </link>
  <!-- Link right_hand -->
  <link name="right_hand">
    <inertial>
      <origin xyz="-0.00441379 0.100801 0.0060602" rpy="0 0 0" />
      <mass value="0.167493" />
      <inertia ixx="0.000456304" ixy="6.09364e-07" ixz="6.11187e-07" iyy="9.83137e-05" iyz="-4.35308e-05" izz="0.000407598" />
    </inertial>
    <!-- Part right_hand_parts -->
    <collision>
      <origin xyz="0.007 0.194 0.0225" rpy="1.5708 -1.5708 0" />
      <geometry>
        <cylinder length="0.06" radius="0.006" />
      </geometry>
    </collision>
    <collision>
      <origin xyz="-0.01 0.1 0.0005" rpy="1.5708 -1.5708 0" />
      <geometry>
        <cylinder length="0.04" radius="0.035" />
      </geometry>
    </collision>
    <visual>
      <origin xyz="-0.00441379 0.100801 0.0060602" rpy="3.14159 -1.5708 0" />
      <geometry>
        <mesh filename="../meshes/visual/right_hand_visual.stl" />
      </geometry>
      <material name="right_hand_parts_material">
        <color rgba="0.935303 0.913041 0.886642 1" />
      </material>
    </visual>
  </link>
  <!-- Frame right_finger2_tip (dummy link + fixed joint) -->
  <link name="right_finger2_tip">
    <origin xyz="0 0 0" rpy="0 -0 0" />
    <inertial>
      <origin xyz="0 0 0" rpy="0 0 0" />
      <mass value="1e-9" />
      <inertia ixx="0" ixy="0" ixz="0" iyy="0" iyz="0" izz="0" />
    </inertial>
  </link>
  <joint name="right_finger2_tip_frame" type="fixed">
    <origin xyz="0.007 0.225 0.0225" rpy="1.5708 0 1.5708" />
    <parent link="right_hand" />
    <child link="right_finger2_tip" />
    <axis xyz="0 0 0" />
  </joint>
  <!-- Joint from right_wrist_roll to right_hand -->
  <joint name="right_wrist_pitch" type="revolute">
    <origin xyz="0 -0 0" rpy="0 1.5708 0" />
    <parent link="right_wrist_roll" />
    <child link="right_hand" />
    <axis xyz="0 0 1" />
    <limit effort="5.5" velocity="100" lower="-0.785398" upper="0.785398" />
    <joint_properties friction="0.1" />
  </joint>
  <!-- Joint from right_wrist_yaw to right_wrist_roll -->
  <joint name="right_wrist_roll" type="revolute">
    <origin xyz="0 -0 -0.135" rpy="-1.5708 0 0" />
    <parent link="right_wrist_yaw" />
    <child link="right_wrist_roll" />
    <axis xyz="0 0 1" />
    <limit effort="5.5" velocity="100" lower="-0.698132" upper="0.698132" />
    <joint_properties friction="0.1" />
  </joint>
  <!-- Joint from right_elbow_pitch to right_wrist_yaw -->
  <joint name="right_wrist_yaw" type="revolute">
    <origin xyz="-0.01 0.055 0" rpy="1.5708 -0 -0" />
    <parent link="right_elbow_pitch" />
    <child link="right_wrist_yaw" />
    <axis xyz="0 0 1" />
    <limit effort="5.5" velocity="100" lower="-1.5708" upper="2.0944" />
    <joint_properties friction="0.1" />
  </joint>
  <!-- Joint from right_shoulder_yaw to right_elbow_pitch -->
  <joint name="right_elbow_pitch" type="revolute">
    <origin xyz="0.01 0 -0.08" rpy="-1.5708 -0 0" />
    <parent link="right_shoulder_yaw" />
    <child link="right_elbow_pitch" />
    <axis xyz="0 0 1" />
    <limit effort="14" velocity="100" lower="-2.35619" upper="0" />
    <joint_properties friction="0.1" />
  </joint>
  <!-- Joint from right_shoulder_roll to right_shoulder_yaw -->
  <joint name="right_shoulder_yaw" type="revolute">
    <origin xyz="-0 0.12 0" rpy="1.5708 -1.5708 0" />
    <parent link="right_shoulder_roll" />
    <child link="right_shoulder_yaw" />
    <axis xyz="0 0 1" />
    <limit effort="14" velocity="100" lower="-1.5708" upper="1.5708" />
    <joint_properties friction="0.1" />
  </joint>
  <!-- Joint from right_shoulder_pitch to right_shoulder_roll -->
  <joint name="right_shoulder_roll" type="revolute">
    <origin xyz="0 -0 0" rpy="-1.5708 0.174533 -1.5708" />
    <parent link="right_shoulder_pitch" />
    <child link="right_shoulder_roll" />
    <axis xyz="0 0 1" />
    <limit effort="14" velocity="100" lower="-1.91986" upper="1.5708" />
    <joint_properties friction="0.1" />
  </joint>
  <!-- Joint from chest to right_shoulder_pitch -->
  <joint name="right_shoulder_pitch" type="revolute">
    <origin xyz="0.02 -0.09 0.36" rpy="-1.74533 -0 0" />
    <parent link="chest" />
    <child link="right_shoulder_pitch" />
    <axis xyz="0 0 1" />
    <limit effort="17" velocity="100" lower="-3.14159" upper="0.785398" />
    <joint_properties friction="0.1" />
  </joint>
</robot>